Workbook
Name _200402: #REF!
Name _200402: #REF!
Name All_Time_High: #REF!
Name All_Time_High: #REF!
Name Alle_Poeng_Alf: #REF!
Name Alle_Poeng_Alf: #REF!
Name Alle_Poeng_Endre: #REF!
Name Alle_Poeng_Endre: #REF!
Name Alle_Poeng_Gjest: #REF!
Name Alle_Poeng_KarlArne: #REF!
Name Alle_Poeng_Lars: #REF!
Name Alle_Poeng_Rune: #REF!
Name Alle_Poeng_Utgang: #REF!
Name Alle_Poeng_Øyvind: #REF!
Name Alle_Siste_Ukes_Poeng: #REF!
Name alltimehigh: #REF!
Name alltimehigh: #REF!
Name alltimelow: #REF!
Name alltimelow: #REF!
Name AntallPremierElveRette: #REF!
Name AntallPremierElveRette: #REF!
Name AntallPremierTiREtte: #REF!
Name AntallPremierTiREtte: #REF!
Name ar_1: #REF!
Name ar_1: #REF!
Name ar_2: #REF!
Name ar_2: #REF!
Name ar_3: #REF!
Name ar_3: #REF!
Name ar_4: #REF!
Name ar_4: #REF!
Name ar_5: #REF!
Name ar_5: #REF!
Name ar_6: #REF!
Name ar_6: #REF!
Name ar_7: #REF!
Name ar_7: #REF!
Name ath: #REF!
Name atl: #REF!
Name attera: #REF!
Name attera: #REF!
Name b_ahh: #REF!
Name b_eb: #REF!
Name b_jh: #REF!
Name b_kaf: #REF!
Name b_rb: #REF!
Name b_toh: #REF!
Name b_øg: #REF!
Name bilde: INDIRECT(#REF!)
Name bilde: INDIRECT(#REF!)
Name bilde: INDIRECT(#REF!)
Name bt: #REF!
Name ccc: #REF!
Name ccc: #REF!
Name cl: #REF!
Name cl: #REF!
Name clo: #REF!
Name clo: #REF!
Name clt: #REF!
Name elvera: #REF!

Sheet Heder & Ære
C2: Årsavslutning 2023-2024 sesongen Skorgen Tippelag
C3: ST Medlemmer | D3: Poeng | E3: Rang | F3: PoengAntall | G3: PoengAntall | H3: PoengAntall | I3: PoengAntall | J3: PoengAntall | K3: PoengAntall | L3: PoengAntall | M3: PoengAntall | N3: Straff | O3: Rangering | P3: Hjemmepoeng | Q3: Uavgjortpoeng | R3: Bortepoeng | S3: Hjemmetreff | T3: Uavgjorttreff | U3: Bortetreff | V3: Antalll koponger | W3: Poengtap | X3: Straff
F4: 80 | G4: 70 | H4: 60 | I4: 50 | J4: 40 | K4: 30 | L4: 20 | M4: 10 | N4: straff | P4: hp | Q4: up | R4: bp | S4: =$S$16 -> 80 | T4: =$S$16 -> 80 | U4: =$S$16 -> 80
C5: AHH | D5: =SUMIFS(INDIRECT("t_"&C5&"[tp]"),INDIRECT("t_"&C5&"[tp]"),"<>""")+X5 -> #REF! | E5: =AVERAGE(INDIRECT("t_"&C5&"[Rank]")) -> #REF! | F5: =COUNTIF(#REF!,F$4) -> #REF! | G5: =COUNTIF(#REF!,G$4) -> #REF! | H5: =COUNTIF(#REF!,H$4) -> #REF! | I5: =COUNTIF(#REF!,I$4) -> #REF! | J5: =COUNTIF(#REF!,J$4) -> #REF! | K5: =COUNTIF(#REF!,K$4) -> #REF! | L5: =COUNTIF(#REF!,L$4) -> #REF! | M5: =COUNTIF(#REF!,M$4) -> #REF! | N5: =(SUM(INDIRECT("t_"&C5&"[Straff]"))/50)*-1 -> #REF! | O5: =_xlfn.RANK.EQ(D5,$D$5:$D$13) -> #REF! | P5: =SUMIFS(INDIRECT("t_"&C5&"[hp]"),INDIRECT("t_"&C5&"[hp]"),"<>""") -> #REF! | Q5: =SUMIFS(INDIRECT("t_"&C5&"[up]"),INDIRECT("t_"&C5&"[up]"),"<>""") -> #REF! | R5: =SUMIFS(INDIRECT("t_"&C5&"[bp]"),INDIRECT("t_"&C5&"[bp]"),"<>""") -> #REF! | S5: =COUNTIF(#REF!,S4) -> #REF! | T5: =COUNTIF(#REF!,T4) -> #REF! | U5: =COUNTIF(#REF!,U4) -> #REF! | V5: =COUNTIF(INDIRECT("t_"&$C5&"[Rank]"),">0") -> #REF! | W5: =(960*$V5)-SUM(P5:R5) -> #REF! | X5: =(SUM(INDIRECT("t_"&C5&"[Straff]"))/50)*-1 -> #REF!
C6: RB | D6: =SUMIFS(INDIRECT("t_"&C6&"[tp]"),INDIRECT("t_"&C6&"[tp]"),"<>""")+X6 -> #REF! | E6: =AVERAGE(INDIRECT("t_"&C6&"[Rank]")) -> #REF! | F6: =COUNTIF(#REF!,F$4) -> #REF! | G6: =COUNTIF(#REF!,G$4) -> #REF! | H6: =COUNTIF(#REF!,H$4) -> #REF! | I6: =COUNTIF(#REF!,I$4) -> #REF! | J6: =COUNTIF(#REF!,J$4) -> #REF! | K6: =COUNTIF(#REF!,K$4) -> #REF! | L6: =COUNTIF(#REF!,L$4) -> #REF! | M6: =COUNTIF(#REF!,M$4) -> #REF! | N6: =(SUM(INDIRECT("t_"&C6&"[Straff]"))/50)*-1 -> #REF! | O6: =_xlfn.RANK.EQ(D6,$D$5:$D$13) -> #REF! | P6: =SUMIFS(INDIRECT("t_"&C6&"[hp]"),INDIRECT("t_"&C6&"[hp]"),"<>""") -> #REF! | Q6: =SUMIFS(INDIRECT("t_"&C6&"[up]"),INDIRECT("t_"&C6&"[up]"),"<>""") -> #REF! | R6: =SUMIFS(INDIRECT("t_"&C6&"[bp]"),INDIRECT("t_"&C6&"[bp]"),"<>""") -> #REF! | S6: =COUNTIF(#REF!,S4) -> #REF! | T6: =COUNTIF(#REF!,T4) -> #REF! | U6: =COUNTIF(#REF!,U4) -> #REF! | V6: =COUNTIF(INDIRECT("t_"&$C6&"[Rank]"),">0") -> #REF! | W6: =(960*$V6)-SUM(P6:R6) -> #REF! | X6: =(SUM(INDIRECT("t_"&C6&"[Straff]"))/50)*-1 -> #REF!
C7: EB | D7: =SUMIFS(INDIRECT("t_"&C7&"[tp]"),INDIRECT("t_"&C7&"[tp]"),"<>""")+X7 -> #REF! | E7: =AVERAGE(INDIRECT("t_"&C7&"[Rank]")) -> #REF! | F7: =COUNTIF(#REF!,F$4) -> #REF! | G7: =COUNTIF(#REF!,G$4) -> #REF! | H7: =COUNTIF(#REF!,H$4) -> #REF! | I7: =COUNTIF(#REF!,I$4) -> #REF! | J7: =COUNTIF(#REF!,J$4) -> #REF! | K7: =COUNTIF(#REF!,K$4) -> #REF! | L7: =COUNTIF(#REF!,L$4) -> #REF! | M7: =COUNTIF(#REF!,M$4) -> #REF! | N7: =(SUM(INDIRECT("t_"&C7&"[Straff]"))/50)*-1 -> #REF! | O7: =_xlfn.RANK.EQ(D7,$D$5:$D$13) -> #REF! | P7: =SUMIFS(INDIRECT("t_"&C7&"[hp]"),INDIRECT("t_"&C7&"[hp]"),"<>""") -> #REF! | Q7: =SUMIFS(INDIRECT("t_"&C7&"[up]"),INDIRECT("t_"&C7&"[up]"),"<>""") -> #REF! | R7: =SUMIFS(INDIRECT("t_"&C7&"[bp]"),INDIRECT("t_"&C7&"[bp]"),"<>""") -> #REF! | S7: =COUNTIF(#REF!,S4) -> #REF! | T7: =COUNTIF(#REF!,T4) -> #REF! | U7: =COUNTIF(#REF!,U4) -> #REF! | V7: =COUNTIF(INDIRECT("t_"&$C7&"[Rank]"),">0") -> #REF! | W7: =(960*$V7)-SUM(P7:R7) -> #REF! | X7: =(SUM(INDIRECT("t_"&C7&"[Straff]"))/50)*-1 -> #REF!
C8: KAF | D8: =SUMIFS(INDIRECT("t_"&C8&"[tp]"),INDIRECT("t_"&C8&"[tp]"),"<>""")+X8 -> #REF! | E8: =AVERAGE(INDIRECT("t_"&C8&"[Rank]")) -> #REF! | F8: =COUNTIF(#REF!,F$4) -> #REF! | G8: =COUNTIF(#REF!,G$4) -> #REF! | H8: =COUNTIF(#REF!,H$4) -> #REF! | I8: =COUNTIF(#REF!,I$4) -> #REF! | J8: =COUNTIF(#REF!,J$4) -> #REF! | K8: =COUNTIF(#REF!,K$4) -> #REF! | L8: =COUNTIF(#REF!,L$4) -> #REF! | M8: =COUNTIF(#REF!,M$4) -> #REF! | N8: =(SUM(INDIRECT("t_"&C8&"[Straff]"))/50)*-1 -> #REF! | O8: =_xlfn.RANK.EQ(D8,$D$5:$D$13) -> #REF! | P8: =SUMIFS(INDIRECT("t_"&C8&"[hp]"),INDIRECT("t_"&C8&"[hp]"),"<>""") -> #REF! | Q8: =SUMIFS(INDIRECT("t_"&C8&"[up]"),INDIRECT("t_"&C8&"[up]"),"<>""") -> #REF! | R8: =SUMIFS(INDIRECT("t_"&C8&"[bp]"),INDIRECT("t_"&C8&"[bp]"),"<>""") -> #REF! | S8: =COUNTIF(#REF!,S4) -> #REF! | T8: =COUNTIF(#REF!,T4) -> #REF! | U8: =COUNTIF(#REF!,U4) -> #REF! | V8: =COUNTIF(INDIRECT("t_"&$C8&"[Rank]"),">0") -> #REF! | W8: =(960*$V8)-SUM(P8:R8) -> #REF! | X8: =(SUM(INDIRECT("t_"&C8&"[Straff]"))/50)*-1 -> #REF!
C9: ØG | D9: =SUMIFS(INDIRECT("t_"&C9&"[tp]"),INDIRECT("t_"&C9&"[tp]"),"<>""")+X9 -> #REF! | E9: =AVERAGE(INDIRECT("t_"&C9&"[Rank]")) -> #REF! | F9: =COUNTIF(#REF!,F$4) -> #REF! | G9: =COUNTIF(#REF!,G$4) -> #REF! | H9: =COUNTIF(#REF!,H$4) -> #REF! | I9: =COUNTIF(#REF!,I$4) -> #REF! | J9: =COUNTIF(#REF!,J$4) -> #REF! | K9: =COUNTIF(#REF!,K$4) -> #REF! | L9: =COUNTIF(#REF!,L$4) -> #REF! | M9: =COUNTIF(#REF!,M$4) -> #REF! | N9: =(SUM(INDIRECT("t_"&C9&"[Straff]"))/50)*-1 -> #REF! | O9: =_xlfn.RANK.EQ(D9,$D$5:$D$13) -> #REF! | P9: =SUMIFS(INDIRECT("t_"&C9&"[hp]"),INDIRECT("t_"&C9&"[hp]"),"<>""") -> #REF! | Q9: =SUMIFS(INDIRECT("t_"&C9&"[up]"),INDIRECT("t_"&C9&"[up]"),"<>""") -> #REF! | R9: =SUMIFS(INDIRECT("t_"&C9&"[bp]"),INDIRECT("t_"&C9&"[bp]"),"<>""") -> #REF! | S9: =COUNTIF(#REF!,S4) -> #REF! | T9: =COUNTIF(#REF!,T4) -> #REF! | U9: =COUNTIF(#REF!,U4) -> #REF! | V9: =COUNTIF(INDIRECT("t_"&$C9&"[Rank]"),">0") -> #REF! | W9: =(960*$V9)-SUM(P9:R9) -> #REF! | X9: =(SUM(INDIRECT("t_"&C9&"[Straff]"))/50)*-1 -> #REF!
C10: JH | D10: =SUMIFS(INDIRECT("t_"&C10&"[tp]"),INDIRECT("t_"&C10&"[tp]"),"<>""")+X10 -> #REF! | E10: =AVERAGE(INDIRECT("t_"&C10&"[Rank]")) -> #REF! | F10: =COUNTIF(#REF!,F$4) -> #REF! | G10: =COUNTIF(#REF!,G$4) -> #REF! | H10: =COUNTIF(#REF!,H$4) -> #REF! | I10: =COUNTIF(#REF!,I$4) -> #REF! | J10: =COUNTIF(#REF!,J$4) -> #REF! | K10: =COUNTIF(#REF!,K$4) -> #REF! | L10: =COUNTIF(#REF!,L$4) -> #REF! | M10: =COUNTIF(#REF!,M$4) -> #REF! | N10: =(SUM(INDIRECT("t_"&C10&"[Straff]"))/50)*-1 -> #REF! | O10: =_xlfn.RANK.EQ(D10,$D$5:$D$13) -> #REF! | P10: =SUMIFS(INDIRECT("t_"&C10&"[hp]"),INDIRECT("t_"&C10&"[hp]"),"<>""") -> #REF! | Q10: =SUMIFS(INDIRECT("t_"&C10&"[up]"),INDIRECT("t_"&C10&"[up]"),"<>""") -> #REF! | R10: =SUMIFS(INDIRECT("t_"&C10&"[bp]"),INDIRECT("t_"&C10&"[bp]"),"<>""") -> #REF! | S10: =COUNTIF(#REF!,S4) -> #REF! | T10: =COUNTIF(#REF!,T4) -> #REF! | U10: =COUNTIF(#REF!,U4) -> #REF! | V10: =COUNTIF(INDIRECT("t_"&$C10&"[Rank]"),">0") -> #REF! | W10: =(960*$V10)-SUM(P10:R10) -> #REF! | X10: =(SUM(INDIRECT("t_"&C10&"[Straff]"))/50)*-1 -> #REF!
C11: TOH | D11: =SUMIFS(INDIRECT("t_"&C11&"[tp]"),INDIRECT("t_"&C11&"[tp]"),"<>""")+X11 -> #REF! | E11: =AVERAGE(INDIRECT("t_"&C11&"[Rank]")) -> #REF! | F11: =COUNTIF(#REF!,F$4) -> #REF! | G11: =COUNTIF(#REF!,G$4) -> #REF! | H11: =COUNTIF(#REF!,H$4) -> #REF! | I11: =COUNTIF(#REF!,I$4) -> #REF! | J11: =COUNTIF(#REF!,J$4) -> #REF! | K11: =COUNTIF(#REF!,K$4) -> #REF! | L11: =COUNTIF(#REF!,L$4) -> #REF! | M11: =COUNTIF(#REF!,M$4) -> #REF! | N11: =(SUM(INDIRECT("t_"&C11&"[Straff]"))/50)*-1 -> #REF! | O11: =_xlfn.RANK.EQ(D11,$D$5:$D$13) -> #REF! | P11: =SUMIFS(INDIRECT("t_"&C11&"[hp]"),INDIRECT("t_"&C11&"[hp]"),"<>""") -> #REF! | Q11: =SUMIFS(INDIRECT("t_"&C11&"[up]"),INDIRECT("t_"&C11&"[up]"),"<>""") -> #REF! | R11: =SUMIFS(INDIRECT("t_"&C11&"[bp]"),INDIRECT("t_"&C11&"[bp]"),"<>""") -> #REF! | S11: =COUNTIF(#REF!,S4) -> #REF! | T11: =COUNTIF(#REF!,T4) -> #REF! | U11: =COUNTIF(#REF!,U4) -> #REF! | V11: =COUNTIF(INDIRECT("t_"&$C11&"[Rank]"),">0") -> #REF! | W11: =(960*$V11)-SUM(P11:R11) -> #REF! | X11: =(SUM(INDIRECT("t_"&C11&"[Straff]"))/50)*-1 -> #REF!
C12: UTG | D12: =SUMIFS(INDIRECT("t_"&C12&"[tp]"),INDIRECT("t_"&C12&"[tp]"),"<>""")+X12 -> #REF! | E12: =AVERAGE(INDIRECT("t_"&C12&"[Rank]")) -> #REF! | F12: =COUNTIF(#REF!,F$4) -> #REF! | G12: =COUNTIF(#REF!,G$4) -> #REF! | H12: =COUNTIF(#REF!,H$4) -> #REF! | I12: =COUNTIF(#REF!,I$4) -> #REF! | J12: =COUNTIF(#REF!,J$4) -> #REF! | K12: =COUNTIF(#REF!,K$4) -> #REF! | L12: =COUNTIF(#REF!,L$4) -> #REF! | M12: =COUNTIF(#REF!,M$4) -> #REF! | N12: =(SUM(INDIRECT("t_"&C12&"[Straff]"))/50)*-1 -> #REF! | O12: =_xlfn.RANK.EQ(D12,$D$5:$D$13) -> #REF! | P12: =SUMIFS(INDIRECT("t_"&C12&"[hp]"),INDIRECT("t_"&C12&"[hp]"),"<>""") -> #REF! | Q12: =SUMIFS(INDIRECT("t_"&C12&"[up]"),INDIRECT("t_"&C12&"[up]"),"<>""") -> #REF! | R12: =SUMIFS(INDIRECT("t_"&C12&"[bp]"),INDIRECT("t_"&C12&"[bp]"),"<>""") -> #REF! | S12: =COUNTIF(#REF!,S4) -> #REF! | T12: =COUNTIF(#REF!,T4) -> #REF! | U12: =COUNTIF(#REF!,U4) -> #REF! | V12: =COUNTIF(INDIRECT("t_"&$C12&"[Rank]"),">0") -> #REF! | W12: =(960*$V12)-SUM(P12:R12) -> #REF! | X12: =(SUM(INDIRECT("t_"&C12&"[Straff]"))/50)*-1 -> #REF!
C13: LEV | D13: =SUMIFS(INDIRECT("t_"&C13&"[tp]"),INDIRECT("t_"&C13&"[tp]"),"<>""")+X13 -> #REF! | E13: =AVERAGE(INDIRECT("t_"&C13&"[Rank]")) -> #REF! | F13: =COUNTIF(#REF!,F$4) -> #REF! | G13: =COUNTIF(#REF!,G$4) -> #REF! | H13: =COUNTIF(#REF!,H$4) -> #REF! | I13: =COUNTIF(#REF!,I$4) -> #REF! | J13: =COUNTIF(#REF!,J$4) -> #REF! | K13: =COUNTIF(#REF!,K$4) -> #REF! | L13: =COUNTIF(#REF!,L$4) -> #REF! | M13: =COUNTIF(#REF!,M$4) -> #REF! | N13: =(SUM(INDIRECT("t_"&C13&"[Straff]"))/50)*-1 -> #REF! | O13: =_xlfn.RANK.EQ(D13,$D$5:$D$13) -> #REF! | P13: =SUMIFS(INDIRECT("t_"&C13&"[hp]"),INDIRECT("t_"&C13&"[hp]"),"<>""") -> #REF! | Q13: =SUMIFS(INDIRECT("t_"&C13&"[up]"),INDIRECT("t_"&C13&"[up]"),"<>""") -> #REF! | R13: =SUMIFS(INDIRECT("t_"&C13&"[bp]"),INDIRECT("t_"&C13&"[bp]"),"<>""") -> #REF! | S13: =COUNTIF(#REF!,S4) -> #REF! | T13: =COUNTIF(#REF!,T4) -> #REF! | U13: =COUNTIF(#REF!,U4) -> #REF! | V13: =COUNTIF(INDIRECT("t_"&$C13&"[Rank]"),">0") -> #REF! | W13: =(960*$V13)-SUM(P13:R13) -> #REF! | X13: =(SUM(INDIRECT("t_"&C13&"[Straff]"))/50)*-1 -> #REF!
P15: Max poeng | Q15: Poenghøst | R15: Poengtap
P16: =960*3*SUM($V$5:$V$13) -> #REF! | Q16: =SUM($P$5:$R$13) -> #REF! | R16: =P16-Q16 -> #REF! | S16: 80
O17: % | P17: {=$P$16:P$16/P$16*100} -> #REF! | Q17: =Q16/P16*100 -> #REF! | R17: =R16/P16*100 -> #REF! | S17: %
R18: ="Trefftabell "&TEXT('Heder & Ære'!$C$4,"dddd, dd.mm.åååå") -> Trefftabell lørdag, 00.01.1900

Sheet Hovedtabell
A1: Navn | B1: hp | C1: up | D1: bp | E1: straff | F1: tp | G1: Summert | H1: 12 Antall | I1: 11 Antall | J1: 10 Antall | K1: 12 poeng | L1: 11 poeng | M1: 10 poeng | N1: LEV-Poeng | O1: Totalt
A2: UTG | B2: 9425 | C2: 0 | D2: 4047 | E2: 0 | F2: 13472 | G2: 13472 | H2: 0 | I2: 0 | J2: 1 | K2: 0 | L2: 0 | M2: 58 | N2: 58 | O2: 13530
A3: EB | B3: 8060 | C3: 1554 | D3: 3621 | E3: 0 | F3: 13235 | G3: 13235 | H3: 0 | I3: 0 | J3: 0 | K3: 0 | L3: 0 | M3: 0 | N3: 0 | O3: 13235
A4: ØG | B4: 8970 | C4: 0 | D4: 3550 | E4: -50 | F4: 12470 | G4: 12470 | H4: 0 | I4: 0 | J4: 2 | K4: 0 | L4: 0 | M4: 116 | N4: 116 | O4: 12586
A5: KAF | B5: 7670 | C5: 444 | D5: 4473 | E5: -50 | F5: 12537 | G5: 12537 | H5: 0 | I5: 0 | J5: 0 | K5: 0 | L5: 0 | M5: 0 | N5: 0 | O5: 12537
A6: RB | B6: 8905 | C6: 296 | D6: 3337 | E6: -100 | F6: 12438 | G6: 12438 | H6: 0 | I6: 0 | J6: 0 | K6: 0 | L6: 0 | M6: 0 | N6: 0 | O6: 12438
A7: LEV | B7: 8320 | C7: 592 | D7: 3479 | E7: 0 | F7: 12391 | G7: 12391 | H7: 0 | I7: 0 | J7: 0 | K7: 0 | L7: 0 | M7: 0 | N7: 0 | O7: 12391
A8: TOH | B8: 8190 | C8: 814 | D8: 3479 | E8: -500 | F8: 11983 | G8: 11983 | H8: 0 | I8: 1 | J8: 1 | K8: 0 | L8: 161 | M8: 58 | N8: 219 | O8: 12202
A9: AHH | B9: 8970 | C9: 740 | D9: 2130 | E9: 0 | F9: 11840 | G9: 11840 | H9: 0 | I9: 0 | J9: 1 | K9: 0 | L9: 0 | M9: 58 | N9: 58 | O9: 11898
A10: JH | B10: 6045 | C10: 1036 | D10: 4473 | E10: -50 | F10: 11504 | G10: 11504 | H10: 0 | I10: 0 | J10: 0 | K10: 0 | L10: 0 | M10: 0 | N10: 0 | O10: 11504

Sheet Analyse
D2: 80 | N2: 70 | X2: 60 | AH2: 50 | AR2: 40 | BB2: 30 | BL2: 20 | BV2: 10
D3: Antall | N3: Antall | X3: Antall | AH3: Antall | AR3: Antall | BB3: Antall | BL3: Antall | BV3: Antall
D4: H | E4: Leverte | F4: %-treff | G4: U | H4: Leverte | I4: %-treff | J4: B | K4: Leverte | L4: %-treff | N4: H | O4: Leverte | P4: %-treff | Q4: U | R4: Leverte | S4: %-treff | T4: B | U4: Leverte | V4: %-treff | X4: H | Y4: Leverte | Z4: %-treff | AA4: U | AB4: Leverte | AC4: %-treff | AD4: B | AE4: Leverte | AF4: %-treff | AH4: H | AI4: Leverte | AJ4: %-treff | AK4: U | AL4: Leverte | AM4: %-treff | AN4: B | AO4: Leverte | AP4: %-treff | AR4: H | AS4: Leverte | AT4: %-treff | AU4: U | AV4: Leverte | AW4: %-treff | AX4: B | AY4: Leverte | AZ4: %-treff | BB4: H | BC4: Leverte | BD4: %-treff | BE4: U | BF4: Leverte | BG4: %-treff | BH4: B | BI4: Leverte | BJ4: %-treff | BL4: H | BM4: Leverte | BN4: %-treff | BO4: U | BP4: Leverte | BQ4: %-treff | BR4: B | BS4: Leverte | BT4: %-treff | BV4: H | BW4: Leverte | BX4: %-treff | BY4: U | BZ4: Leverte | CA4: %-treff | CB4: B | CC4: Leverte | CD4: %-treff
C5: RB | D5: =IFERROR(COUNTIF(#REF!,D$2),0) -> 0 | E5: =IFERROR(COUNTIF(#REF!,Analyse!D$2),0) -> 0 | F5: =IFERROR(D5/E5,0) -> 0 | G5: =IFERROR(COUNTIF(#REF!,D$2),0) -> 0 | H5: =IFERROR(COUNTIF(#REF!,Analyse!D$2),0) -> 0 | I5: =IFERROR(G5/H5,0) -> 0 | J5: =IFERROR(COUNTIF(#REF!,D$2),0) -> 0 | K5: =IFERROR(COUNTIF(#REF!,Analyse!D$2),0) -> 0 | L5: =IFERROR(J5/K5,0) -> 0 | M5: RB | N5: =IFERROR(COUNTIF(#REF!,N$2),0) -> 0 | O5: =IFERROR(COUNTIF(#REF!,Analyse!N$2),0) -> 0 | P5: =IFERROR(N5/O5,0) -> 0 | Q5: =IFERROR(COUNTIF(#REF!,N$2),0) -> 0 | R5: =IFERROR(COUNTIF(#REF!,Analyse!N$2),0) -> 0 | S5: =IFERROR(Q5/R5,0) -> 0 | T5: =IFERROR(COUNTIF(#REF!,N$2),0) -> 0 | U5: =IFERROR(COUNTIF(#REF!,Analyse!N$2),0) -> 0 | V5: =IFERROR(T5/U5,0) -> 0 | W5: AHH | X5: =IFERROR(COUNTIF(#REF!,X$2),0) -> 0 | Y5: =IFERROR(COUNTIF(#REF!,Analyse!X$2),0) -> 0 | Z5: =IFERROR(X5/Y5,0) -> 0 | AA5: =IFERROR(COUNTIF(#REF!,X$2),0) -> 0 | AB5: =IFERROR(COUNTIF(#REF!,Analyse!X$2),0) -> 0 | AC5: =IFERROR(AA5/AB5,0) -> 0 | AD5: =IFERROR(COUNTIF(#REF!,X$2),0) -> 0 | AE5: =IFERROR(COUNTIF(#REF!,Analyse!X$2),0) -> 0 | AF5: =IFERROR(AD5/AE5,0) -> 0 | AG5: JH | AH5: =IFERROR(COUNTIF(#REF!,AH$2),0) -> 0 | AI5: =IFERROR(COUNTIF(#REF!,Analyse!AH$2),0) -> 0 | AJ5: =IFERROR(AH5/AI5,0) -> 0 | AK5: =IFERROR(COUNTIF(#REF!,AH$2),0) -> 0 | AL5: =IFERROR(COUNTIF(#REF!,Analyse!AH$2),0) -> 0 | AM5: =IFERROR(AK5/AL5,0) -> 0 | AN5: =IFERROR(COUNTIF(#REF!,AH$2),0) -> 0 | AO5: =IFERROR(COUNTIF(#REF!,Analyse!AH$2),0) -> 0 | AP5: =IFERROR(AN5/AO5,0) -> 0 | AQ5: TOH | AR5: =IFERROR(COUNTIF(#REF!,AR$2),0) -> 0 | AS5: =IFERROR(COUNTIF(#REF!,Analyse!AR$2),0) -> 0 | AT5: =IFERROR(AR5/AS5,0) -> 0 | AU5: =IFERROR(COUNTIF(#REF!,AR$2),0) -> 0 | AV5: =IFERROR(COUNTIF(#REF!,Analyse!AR$2),0) -> 0 | AW5: =IFERROR(AU5/AV5,0) -> 0 | AX5: =IFERROR(COUNTIF(#REF!,AR$2),0) -> 0 | AY5: =IFERROR(COUNTIF(#REF!,Analyse!AR$2),0) -> 0 | AZ5: =IFERROR(AX5/AY5,0) -> 0 | BA5: EB | BB5: =IFERROR(COUNTIF(#REF!,BB$2),0) -> 0 | BC5: =IFERROR(COUNTIF(#REF!,Analyse!BB$2),0) -> 0 | BD5: =IFERROR(BB5/BC5,0) -> 0 | BE5: =IFERROR(COUNTIF(#REF!,BB$2),0) -> 0 | BF5: =IFERROR(COUNTIF(#REF!,Analyse!BB$2),0) -> 0 | BG5: =IFERROR(BE5/BF5,0) -> 0 | BH5: =IFERROR(COUNTIF(#REF!,BB$2),0) -> 0 | BI5: =IFERROR(COUNTIF(#REF!,Analyse!BB$2),0) -> 0 | BJ5: =IFERROR(BH5/BI5,0) -> 0 | BK5: KAF | BL5: =IFERROR(COUNTIF(#REF!,BL$2),0) -> 0 | BM5: =IFERROR(COUNTIF(#REF!,Analyse!BL$2),0) -> 0 | BN5: =IFERROR(BL5/BM5,0) -> 0 | BO5: =IFERROR(COUNTIF(#REF!,BL$2),0) -> 0 | BP5: =IFERROR(COUNTIF(#REF!,Analyse!BL$2),0) -> 0 | BQ5: =IFERROR(BO5/BP5,0) -> 0 | BR5: =IFERROR(COUNTIF(#REF!,BL$2),0) -> 0 | BS5: =IFERROR(COUNTIF(#REF!,Analyse!BL$2),0) -> 0 | BT5: =IFERROR(BR5/BS5,0) -> 0 | BU5: AHH | BV5: =IFERROR(COUNTIF(#REF!,BV$2),0) -> 0 | BW5: =IFERROR(COUNTIF(#REF!,Analyse!BV$2),0) -> 0 | BX5: =IFERROR(BV5/BW5,0) -> 0 | BY5: =IFERROR(COUNTIF(#REF!,BV$2),0) -> 0 | BZ5: =IFERROR(COUNTIF(#REF!,Analyse!BV$2),0) -> 0 | CA5: =IFERROR(BY5/BZ5,0) -> 0 | CB5: =IFERROR(COUNTIF(#REF!,BV$2),0) -> 0 | CC5: =IFERROR(COUNTIF(#REF!,Analyse!BV$2),0) -> 0 | CD5: =IFERROR(CB5/CC5,0) -> 0
C6: TOH | D6: =IFERROR(COUNTIF(#REF!,D$2),0) -> 0 | E6: =IFERROR(COUNTIF(#REF!,Analyse!D$2),0) -> 0 | F6: =IFERROR(D6/E6,0) -> 0 | G6: =IFERROR(COUNTIF(#REF!,D$2),0) -> 0 | H6: =IFERROR(COUNTIF(#REF!,Analyse!D$2),0) -> 0 | I6: =IFERROR(G6/H6,0) -> 0 | J6: =IFERROR(COUNTIF(#REF!,D$2),0) -> 0 | K6: =IFERROR(COUNTIF(#REF!,Analyse!D$2),0) -> 0 | L6: =IFERROR(J6/K6,0) -> 0 | M6: KAF | N6: =IFERROR(COUNTIF(#REF!,N$2),0) -> 0 | O6: =IFERROR(COUNTIF(#REF!,Analyse!N$2),0) -> 0 | P6: =IFERROR(N6/O6,0) -> 0 | Q6: =IFERROR(COUNTIF(#REF!,N$2),0) -> 0 | R6: =IFERROR(COUNTIF(#REF!,Analyse!N$2),0) -> 0 | S6: =IFERROR(Q6/R6,0) -> 0 | T6: =IFERROR(COUNTIF(#REF!,N$2),0) -> 0 | U6: =IFERROR(COUNTIF(#REF!,Analyse!N$2),0) -> 0 | V6: =IFERROR(T6/U6,0) -> 0 | W6: EB | X6: =IFERROR(COUNTIF(#REF!,X$2),0) -> 0 | Y6: =IFERROR(COUNTIF(#REF!,Analyse!X$2),0) -> 0 | Z6: =IFERROR(X6/Y6,0) -> 0 | AA6: =IFERROR(COUNTIF(#REF!,X$2),0) -> 0 | AB6: =IFERROR(COUNTIF(#REF!,Analyse!X$2),0) -> 0 | AC6: =IFERROR(AA6/AB6,0) -> 0 | AD6: =IFERROR(COUNTIF(#REF!,X$2),0) -> 0 | AE6: =IFERROR(COUNTIF(#REF!,Analyse!X$2),0) -> 0 | AF6: =IFERROR(AD6/AE6,0) -> 0 | AG6: EB | AH6: =IFERROR(COUNTIF(#REF!,AH$2),0) -> 0 | AI6: =IFERROR(COUNTIF(#REF!,Analyse!AH$2),0) -> 0 | AJ6: =IFERROR(AH6/AI6,0) -> 0 | AK6: =IFERROR(COUNTIF(#REF!,AH$2),0) -> 0 | AL6: =IFERROR(COUNTIF(#REF!,Analyse!AH$2),0) -> 0 | AM6: =IFERROR(AK6/AL6,0) -> 0 | AN6: =IFERROR(COUNTIF(#REF!,AH$2),0) -> 0 | AO6: =IFERROR(COUNTIF(#REF!,Analyse!AH$2),0) -> 0 | AP6: =IFERROR(AN6/AO6,0) -> 0 | AQ6: ØG | AR6: =IFERROR(COUNTIF(#REF!,AR$2),0) -> 0 | AS6: =IFERROR(COUNTIF(#REF!,Analyse!AR$2),0) -> 0 | AT6: =IFERROR(AR6/AS6,0) -> 0 | AU6: =IFERROR(COUNTIF(#REF!,AR$2),0) -> 0 | AV6: =IFERROR(COUNTIF(#REF!,Analyse!AR$2),0) -> 0 | AW6: =IFERROR(AU6/AV6,0) -> 0 | AX6: =IFERROR(COUNTIF(#REF!,AR$2),0) -> 0 | AY6: =IFERROR(COUNTIF(#REF!,Analyse!AR$2),0) -> 0 | AZ6: =IFERROR(AX6/AY6,0) -> 0 | BA6: ØG | BB6: =IFERROR(COUNTIF(#REF!,BB$2),0) -> 0 | BC6: =IFERROR(COUNTIF(#REF!,Analyse!BB$2),0) -> 0 | BD6: =IFERROR(BB6/BC6,0) -> 0 | BE6: =IFERROR(COUNTIF(#REF!,BB$2),0) -> 0 | BF6: =IFERROR(COUNTIF(#REF!,Analyse!BB$2),0) -> 0 | BG6: =IFERROR(BE6/BF6,0) -> 0 | BH6: =IFERROR(COUNTIF(#REF!,BB$2),0) -> 0 | BI6: =IFERROR(COUNTIF(#REF!,Analyse!BB$2),0) -> 0 | BJ6: =IFERROR(BH6/BI6,0) -> 0 | BK6: RB | BL6: =IFERROR(COUNTIF(#REF!,BL$2),0) -> 0 | BM6: =IFERROR(COUNTIF(#REF!,Analyse!BL$2),0) -> 0 | BN6: =IFERROR(BL6/BM6,0) -> 0 | BO6: =IFERROR(COUNTIF(#REF!,BL$2),0) -> 0 | BP6: =IFERROR(COUNTIF(#REF!,Analyse!BL$2),0) -> 0 | BQ6: =IFERROR(BO6/BP6,0) -> 0 | BR6: =IFERROR(COUNTIF(#REF!,BL$2),0) -> 0 | BS6: =IFERROR(COUNTIF(#REF!,Analyse!BL$2),0) -> 0 | BT6: =IFERROR(BR6/BS6,0) -> 0 | BU6: TOH | BV6: =IFERROR(COUNTIF(#REF!,BV$2),0) -> 0 | BW6: =IFERROR(COUNTIF(#REF!,Analyse!BV$2),0) -> 0 | BX6: =IFERROR(BV6/BW6,0) -> 0 | BY6: =IFERROR(COUNTIF(#REF!,BV$2),0) -> 0 | BZ6: =IFERROR(COUNTIF(#REF!,Analyse!BV$2),0) -> 0 | CA6: =IFERROR(BY6/BZ6,0) -> 0 | CB6: =IFERROR(COUNTIF(#REF!,BV$2),0) -> 0 | CC6: =IFERROR(COUNTIF(#REF!,Analyse!BV$2),0) -> 0 | CD6: =IFERROR(CB6/CC6,0) -> 0
C7: EB | D7: =IFERROR(COUNTIF(#REF!,D$2),0) -> 0 | E7: =IFERROR(COUNTIF(#REF!,Analyse!D$2),0) -> 0 | F7: =IFERROR(D7/E7,0) -> 0 | G7: =IFERROR(COUNTIF(#REF!,D$2),0) -> 0 | H7: =IFERROR(COUNTIF(#REF!,Analyse!D$2),0) -> 0 | I7: =IFERROR(G7/H7,0) -> 0 | J7: =IFERROR(COUNTIF(#REF!,D$2),0) -> 0 | K7: =IFERROR(COUNTIF(#REF!,Analyse!D$2),0) -> 0 | L7: =IFERROR(J7/K7,0) -> 0 | M7: ØG | N7: =IFERROR(COUNTIF(#REF!,N$2),0) -> 0 | O7: =IFERROR(COUNTIF(#REF!,Analyse!N$2),0) -> 0 | P7: =IFERROR(N7/O7,0) -> 0 | Q7: =IFERROR(COUNTIF(#REF!,N$2),0) -> 0 | R7: =IFERROR(COUNTIF(#REF!,Analyse!N$2),0) -> 0 | S7: =IFERROR(Q7/R7,0) -> 0 | T7: =IFERROR(COUNTIF(#REF!,N$2),0) -> 0 | U7: =IFERROR(COUNTIF(#REF!,Analyse!N$2),0) -> 0 | V7: =IFERROR(T7/U7,0) -> 0 | W7: JH | X7: =IFERROR(COUNTIF(#REF!,X$2),0) -> 0 | Y7: =IFERROR(COUNTIF(#REF!,Analyse!X$2),0) -> 0 | Z7: =IFERROR(X7/Y7,0) -> 0 | AA7: =IFERROR(COUNTIF(#REF!,X$2),0) -> 0 | AB7: =IFERROR(COUNTIF(#REF!,Analyse!X$2),0) -> 0 | AC7: =IFERROR(AA7/AB7,0) -> 0 | AD7: =IFERROR(COUNTIF(#REF!,X$2),0) -> 0 | AE7: =IFERROR(COUNTIF(#REF!,Analyse!X$2),0) -> 0 | AF7: =IFERROR(AD7/AE7,0) -> 0 | AG7: UTG | AH7: =IFERROR(COUNTIF(#REF!,AH$2),0) -> 0 | AI7: =IFERROR(COUNTIF(#REF!,Analyse!AH$2),0) -> 0 | AJ7: =IFERROR(AH7/AI7,0) -> 0 | AK7: =IFERROR(COUNTIF(#REF!,AH$2),0) -> 0 | AL7: =IFERROR(COUNTIF(#REF!,Analyse!AH$2),0) -> 0 | AM7: =IFERROR(AK7/AL7,0) -> 0 | AN7: =IFERROR(COUNTIF(#REF!,AH$2),0) -> 0 | AO7: =IFERROR(COUNTIF(#REF!,Analyse!AH$2),0) -> 0 | AP7: =IFERROR(AN7/AO7,0) -> 0 | AQ7: LEV | AR7: =IFERROR(COUNTIF(#REF!,AR$2),0) -> 0 | AS7: =IFERROR(COUNTIF(#REF!,Analyse!AR$2),0) -> 0 | AT7: =IFERROR(AR7/AS7,0) -> 0 | AU7: =IFERROR(COUNTIF(#REF!,AR$2),0) -> 0 | AV7: =IFERROR(COUNTIF(#REF!,Analyse!AR$2),0) -> 0 | AW7: =IFERROR(AU7/AV7,0) -> 0 | AX7: =IFERROR(COUNTIF(#REF!,AR$2),0) -> 0 | AY7: =IFERROR(COUNTIF(#REF!,Analyse!AR$2),0) -> 0 | AZ7: =IFERROR(AX7/AY7,0) -> 0 | BA7: TOH | BB7: =IFERROR(COUNTIF(#REF!,BB$2),0) -> 0 | BC7: =IFERROR(COUNTIF(#REF!,Analyse!BB$2),0) -> 0 | BD7: =IFERROR(BB7/BC7,0) -> 0 | BE7: =IFERROR(COUNTIF(#REF!,BB$2),0) -> 0 | BF7: =IFERROR(COUNTIF(#REF!,Analyse!BB$2),0) -> 0 | BG7: =IFERROR(BE7/BF7,0) -> 0 | BH7: =IFERROR(COUNTIF(#REF!,BB$2),0) -> 0 | BI7: =IFERROR(COUNTIF(#REF!,Analyse!BB$2),0) -> 0 | BJ7: =IFERROR(BH7/BI7,0) -> 0 | BK7: LEV | BL7: =IFERROR(COUNTIF(#REF!,BL$2),0) -> 0 | BM7: =IFERROR(COUNTIF(#REF!,Analyse!BL$2),0) -> 0 | BN7: =IFERROR(BL7/BM7,0) -> 0 | BO7: =IFERROR(COUNTIF(#REF!,BL$2),0) -> 0 | BP7: =IFERROR(COUNTIF(#REF!,Analyse!BL$2),0) -> 0 | BQ7: =IFERROR(BO7/BP7,0) -> 0 | BR7: =IFERROR(COUNTIF(#REF!,BL$2),0) -> 0 | BS7: =IFERROR(COUNTIF(#REF!,Analyse!BL$2),0) -> 0 | BT7: =IFERROR(BR7/BS7,0) -> 0 | BU7: JH | BV7: =IFERROR(COUNTIF(#REF!,BV$2),0) -> 0 | BW7: =IFERROR(COUNTIF(#REF!,Analyse!BV$2),0) -> 0 | BX7: =IFERROR(BV7/BW7,0) -> 0 | BY7: =IFERROR(COUNTIF(#REF!,BV$2),0) -> 0 | BZ7: =IFERROR(COUNTIF(#REF!,Analyse!BV$2),0) -> 0 | CA7: =IFERROR(BY7/BZ7,0) -> 0 | CB7: =IFERROR(COUNTIF(#REF!,BV$2),0) -> 0 | CC7: =IFERROR(COUNTIF(#REF!,Analyse!BV$2),0) -> 0 | CD7: =IFERROR(CB7/CC7,0) -> 0
C8: AHH | D8: =IFERROR(COUNTIF(#REF!,D$2),0) -> 0 | E8: =IFERROR(COUNTIF(#REF!,Analyse!D$2),0) -> 0 | F8: =IFERROR(D8/E8,0) -> 0 | G8: =IFERROR(COUNTIF(#REF!,D$2),0) -> 0 | H8: =IFERROR(COUNTIF(#REF!,Analyse!D$2),0) -> 0 | I8: =IFERROR(G8/H8,0) -> 0 | J8: =IFERROR(COUNTIF(#REF!,D$2),0) -> 0 | K8: =IFERROR(COUNTIF(#REF!,Analyse!D$2),0) -> 0 | L8: =IFERROR(J8/K8,0) -> 0 | M8: AHH | N8: =IFERROR(COUNTIF(#REF!,N$2),0) -> 0 | O8: =IFERROR(COUNTIF(#REF!,Analyse!N$2),0) -> 0 | P8: =IFERROR(N8/O8,0) -> 0 | Q8: =IFERROR(COUNTIF(#REF!,N$2),0) -> 0 | R8: =IFERROR(COUNTIF(#REF!,Analyse!N$2),0) -> 0 | S8: =IFERROR(Q8/R8,0) -> 0 | T8: =IFERROR(COUNTIF(#REF!,N$2),0) -> 0 | U8: =IFERROR(COUNTIF(#REF!,Analyse!N$2),0) -> 0 | V8: =IFERROR(T8/U8,0) -> 0 | W8: LEV | X8: =IFERROR(COUNTIF(#REF!,X$2),0) -> 0 | Y8: =IFERROR(COUNTIF(#REF!,Analyse!X$2),0) -> 0 | Z8: =IFERROR(X8/Y8,0) -> 0 | AA8: =IFERROR(COUNTIF(#REF!,X$2),0) -> 0 | AB8: =IFERROR(COUNTIF(#REF!,Analyse!X$2),0) -> 0 | AC8: =IFERROR(AA8/AB8,0) -> 0 | AD8: =IFERROR(COUNTIF(#REF!,X$2),0) -> 0 | AE8: =IFERROR(COUNTIF(#REF!,Analyse!X$2),0) -> 0 | AF8: =IFERROR(AD8/AE8,0) -> 0 | AG8: KAF | AH8: =IFERROR(COUNTIF(#REF!,AH$2),0) -> 0 | AI8: =IFERROR(COUNTIF(#REF!,Analyse!AH$2),0) -> 0 | AJ8: =IFERROR(AH8/AI8,0) -> 0 | AK8: =IFERROR(COUNTIF(#REF!,AH$2),0) -> 0 | AL8: =IFERROR(COUNTIF(#REF!,Analyse!AH$2),0) -> 0 | AM8: =IFERROR(AK8/AL8,0) -> 0 | AN8: =IFERROR(COUNTIF(#REF!,AH$2),0) -> 0 | AO8: =IFERROR(COUNTIF(#REF!,Analyse!AH$2),0) -> 0 | AP8: =IFERROR(AN8/AO8,0) -> 0 | AQ8: KAF | AR8: =IFERROR(COUNTIF(#REF!,AR$2),0) -> 0 | AS8: =IFERROR(COUNTIF(#REF!,Analyse!AR$2),0) -> 0 | AT8: =IFERROR(AR8/AS8,0) -> 0 | AU8: =IFERROR(COUNTIF(#REF!,AR$2),0) -> 0 | AV8: =IFERROR(COUNTIF(#REF!,Analyse!AR$2),0) -> 0 | AW8: =IFERROR(AU8/AV8,0) -> 0 | AX8: =IFERROR(COUNTIF(#REF!,AR$2),0) -> 0 | AY8: =IFERROR(COUNTIF(#REF!,Analyse!AR$2),0) -> 0 | AZ8: =IFERROR(AX8/AY8,0) -> 0 | BA8: AHH | BB8: =IFERROR(COUNTIF(#REF!,BB$2),0) -> 0 | BC8: =IFERROR(COUNTIF(#REF!,Analyse!BB$2),0) -> 0 | BD8: =IFERROR(BB8/BC8,0) -> 0 | BE8: =IFERROR(COUNTIF(#REF!,BB$2),0) -> 0 | BF8: =IFERROR(COUNTIF(#REF!,Analyse!BB$2),0) -> 0 | BG8: =IFERROR(BE8/BF8,0) -> 0 | BH8: =IFERROR(COUNTIF(#REF!,BB$2),0) -> 0 | BI8: =IFERROR(COUNTIF(#REF!,Analyse!BB$2),0) -> 0 | BJ8: =IFERROR(BH8/BI8,0) -> 0 | BK8: UTG | BL8: =IFERROR(COUNTIF(#REF!,BL$2),0) -> 0 | BM8: =IFERROR(COUNTIF(#REF!,Analyse!BL$2),0) -> 0 | BN8: =IFERROR(BL8/BM8,0) -> 0 | BO8: =IFERROR(COUNTIF(#REF!,BL$2),0) -> 0 | BP8: =IFERROR(COUNTIF(#REF!,Analyse!BL$2),0) -> 0 | BQ8: =IFERROR(BO8/BP8,0) -> 0 | BR8: =IFERROR(COUNTIF(#REF!,BL$2),0) -> 0 | BS8: =IFERROR(COUNTIF(#REF!,Analyse!BL$2),0) -> 0 | BT8: =IFERROR(BR8/BS8,0) -> 0 | BU8: KAF | BV8: =IFERROR(COUNTIF(#REF!,BV$2),0) -> 0 | BW8: =IFERROR(COUNTIF(#REF!,Analyse!BV$2),0) -> 0 | BX8: =IFERROR(BV8/BW8,0) -> 0 | BY8: =IFERROR(COUNTIF(#REF!,BV$2),0) -> 0 | BZ8: =IFERROR(COUNTIF(#REF!,Analyse!BV$2),0) -> 0 | CA8: =IFERROR(BY8/BZ8,0) -> 0 | CB8: =IFERROR(COUNTIF(#REF!,BV$2),0) -> 0 | CC8: =IFERROR(COUNTIF(#REF!,Analyse!BV$2),0) -> 0 | CD8: =IFERROR(CB8/CC8,0) -> 0
C9: UTG | D9: =IFERROR(COUNTIF(#REF!,D$2),0) -> 0 | E9: =IFERROR(COUNTIF(#REF!,Analyse!D$2),0) -> 0 | F9: =IFERROR(D9/E9,0) -> 0 | G9: =IFERROR(COUNTIF(#REF!,D$2),0) -> 0 | H9: =IFERROR(COUNTIF(#REF!,Analyse!D$2),0) -> 0 | I9: =IFERROR(G9/H9,0) -> 0 | J9: =IFERROR(COUNTIF(#REF!,D$2),0) -> 0 | K9: =IFERROR(COUNTIF(#REF!,Analyse!D$2),0) -> 0 | L9: =IFERROR(J9/K9,0) -> 0 | M9: LEV | N9: =IFERROR(COUNTIF(#REF!,N$2),0) -> 0 | O9: =IFERROR(COUNTIF(#REF!,Analyse!N$2),0) -> 0 | P9: =IFERROR(N9/O9,0) -> 0 | Q9: =IFERROR(COUNTIF(#REF!,N$2),0) -> 0 | R9: =IFERROR(COUNTIF(#REF!,Analyse!N$2),0) -> 0 | S9: =IFERROR(Q9/R9,0) -> 0 | T9: =IFERROR(COUNTIF(#REF!,N$2),0) -> 0 | U9: =IFERROR(COUNTIF(#REF!,Analyse!N$2),0) -> 0 | V9: =IFERROR(T9/U9,0) -> 0 | W9: UTG | X9: =IFERROR(COUNTIF(#REF!,X$2),0) -> 0 | Y9: =IFERROR(COUNTIF(#REF!,Analyse!X$2),0) -> 0 | Z9: =IFERROR(X9/Y9,0) -> 0 | AA9: =IFERROR(COUNTIF(#REF!,X$2),0) -> 0 | AB9: =IFERROR(COUNTIF(#REF!,Analyse!X$2),0) -> 0 | AC9: =IFERROR(AA9/AB9,0) -> 0 | AD9: =IFERROR(COUNTIF(#REF!,X$2),0) -> 0 | AE9: =IFERROR(COUNTIF(#REF!,Analyse!X$2),0) -> 0 | AF9: =IFERROR(AD9/AE9,0) -> 0 | AG9: LEV | AH9: =IFERROR(COUNTIF(#REF!,AH$2),0) -> 0 | AI9: =IFERROR(COUNTIF(#REF!,Analyse!AH$2),0) -> 0 | AJ9: =IFERROR(AH9/AI9,0) -> 0 | AK9: =IFERROR(COUNTIF(#REF!,AH$2),0) -> 0 | AL9: =IFERROR(COUNTIF(#REF!,Analyse!AH$2),0) -> 0 | AM9: =IFERROR(AK9/AL9,0) -> 0 | AN9: =IFERROR(COUNTIF(#REF!,AH$2),0) -> 0 | AO9: =IFERROR(COUNTIF(#REF!,Analyse!AH$2),0) -> 0 | AP9: =IFERROR(AN9/AO9,0) -> 0 | AQ9: AHH | AR9: =IFERROR(COUNTIF(#REF!,AR$2),0) -> 0 | AS9: =IFERROR(COUNTIF(#REF!,Analyse!AR$2),0) -> 0 | AT9: =IFERROR(AR9/AS9,0) -> 0 | AU9: =IFERROR(COUNTIF(#REF!,AR$2),0) -> 0 | AV9: =IFERROR(COUNTIF(#REF!,Analyse!AR$2),0) -> 0 | AW9: =IFERROR(AU9/AV9,0) -> 0 | AX9: =IFERROR(COUNTIF(#REF!,AR$2),0) -> 0 | AY9: =IFERROR(COUNTIF(#REF!,Analyse!AR$2),0) -> 0 | AZ9: =IFERROR(AX9/AY9,0) -> 0 | BA9: LEV | BB9: =IFERROR(COUNTIF(#REF!,BB$2),0) -> 0 | BC9: =IFERROR(COUNTIF(#REF!,Analyse!BB$2),0) -> 0 | BD9: =IFERROR(BB9/BC9,0) -> 0 | BE9: =IFERROR(COUNTIF(#REF!,BB$2),0) -> 0 | BF9: =IFERROR(COUNTIF(#REF!,Analyse!BB$2),0) -> 0 | BG9: =IFERROR(BE9/BF9,0) -> 0 | BH9: =IFERROR(COUNTIF(#REF!,BB$2),0) -> 0 | BI9: =IFERROR(COUNTIF(#REF!,Analyse!BB$2),0) -> 0 | BJ9: =IFERROR(BH9/BI9,0) -> 0 | BK9: ØG | BL9: =IFERROR(COUNTIF(#REF!,BL$2),0) -> 0 | BM9: =IFERROR(COUNTIF(#REF!,Analyse!BL$2),0) -> 0 | BN9: =IFERROR(BL9/BM9,0) -> 0 | BO9: =IFERROR(COUNTIF(#REF!,BL$2),0) -> 0 | BP9: =IFERROR(COUNTIF(#REF!,Analyse!BL$2),0) -> 0 | BQ9: =IFERROR(BO9/BP9,0) -> 0 | BR9: =IFERROR(COUNTIF(#REF!,BL$2),0) -> 0 | BS9: =IFERROR(COUNTIF(#REF!,Analyse!BL$2),0) -> 0 | BT9: =IFERROR(BR9/BS9,0) -> 0 | BU9: RB | BV9: =IFERROR(COUNTIF(#REF!,BV$2),0) -> 0 | BW9: =IFERROR(COUNTIF(#REF!,Analyse!BV$2),0) -> 0 | BX9: =IFERROR(BV9/BW9,0) -> 0 | BY9: =IFERROR(COUNTIF(#REF!,BV$2),0) -> 0 | BZ9: =IFERROR(COUNTIF(#REF!,Analyse!BV$2),0) -> 0 | CA9: =IFERROR(BY9/BZ9,0) -> 0 | CB9: =IFERROR(COUNTIF(#REF!,BV$2),0) -> 0 | CC9: =IFERROR(COUNTIF(#REF!,Analyse!BV$2),0) -> 0 | CD9: =IFERROR(CB9/CC9,0) -> 0
C10: LEV | D10: =IFERROR(COUNTIF(#REF!,D$2),0) -> 0 | E10: =IFERROR(COUNTIF(#REF!,Analyse!D$2),0) -> 0 | F10: =IFERROR(D10/E10,0) -> 0 | G10: =IFERROR(COUNTIF(#REF!,D$2),0) -> 0 | H10: =IFERROR(COUNTIF(#REF!,Analyse!D$2),0) -> 0 | I10: =IFERROR(G10/H10,0) -> 0 | J10: =IFERROR(COUNTIF(#REF!,D$2),0) -> 0 | K10: =IFERROR(COUNTIF(#REF!,Analyse!D$2),0) -> 0 | L10: =IFERROR(J10/K10,0) -> 0 | M10: UTG | N10: =IFERROR(COUNTIF(#REF!,N$2),0) -> 0 | O10: =IFERROR(COUNTIF(#REF!,Analyse!N$2),0) -> 0 | P10: =IFERROR(N10/O10,0) -> 0 | Q10: =IFERROR(COUNTIF(#REF!,N$2),0) -> 0 | R10: =IFERROR(COUNTIF(#REF!,Analyse!N$2),0) -> 0 | S10: =IFERROR(Q10/R10,0) -> 0 | T10: =IFERROR(COUNTIF(#REF!,N$2),0) -> 0 | U10: =IFERROR(COUNTIF(#REF!,Analyse!N$2),0) -> 0 | V10: =IFERROR(T10/U10,0) -> 0 | W10: RB | X10: =IFERROR(COUNTIF(#REF!,X$2),0) -> 0 | Y10: =IFERROR(COUNTIF(#REF!,Analyse!X$2),0) -> 0 | Z10: =IFERROR(X10/Y10,0) -> 0 | AA10: =IFERROR(COUNTIF(#REF!,X$2),0) -> 0 | AB10: =IFERROR(COUNTIF(#REF!,Analyse!X$2),0) -> 0 | AC10: =IFERROR(AA10/AB10,0) -> 0 | AD10: =IFERROR(COUNTIF(#REF!,X$2),0) -> 0 | AE10: =IFERROR(COUNTIF(#REF!,Analyse!X$2),0) -> 0 | AF10: =IFERROR(AD10/AE10,0) -> 0 | AG10: RB | AH10: =IFERROR(COUNTIF(#REF!,AH$2),0) -> 0 | AI10: =IFERROR(COUNTIF(#REF!,Analyse!AH$2),0) -> 0 | AJ10: =IFERROR(AH10/AI10,0) -> 0 | AK10: =IFERROR(COUNTIF(#REF!,AH$2),0) -> 0 | AL10: =IFERROR(COUNTIF(#REF!,Analyse!AH$2),0) -> 0 | AM10: =IFERROR(AK10/AL10,0) -> 0 | AN10: =IFERROR(COUNTIF(#REF!,AH$2),0) -> 0 | AO10: =IFERROR(COUNTIF(#REF!,Analyse!AH$2),0) -> 0 | AP10: =IFERROR(AN10/AO10,0) -> 0 | AQ10: UTG | AR10: =IFERROR(COUNTIF(#REF!,AR$2),0) -> 0 | AS10: =IFERROR(COUNTIF(#REF!,Analyse!AR$2),0) -> 0 | AT10: =IFERROR(AR10/AS10,0) -> 0 | AU10: =IFERROR(COUNTIF(#REF!,AR$2),0) -> 0 | AV10: =IFERROR(COUNTIF(#REF!,Analyse!AR$2),0) -> 0 | AW10: =IFERROR(AU10/AV10,0) -> 0 | AX10: =IFERROR(COUNTIF(#REF!,AR$2),0) -> 0 | AY10: =IFERROR(COUNTIF(#REF!,Analyse!AR$2),0) -> 0 | AZ10: =IFERROR(AX10/AY10,0) -> 0 | BA10: JH | BB10: =IFERROR(COUNTIF(#REF!,BB$2),0) -> 0 | BC10: =IFERROR(COUNTIF(#REF!,Analyse!BB$2),0) -> 0 | BD10: =IFERROR(BB10/BC10,0) -> 0 | BE10: =IFERROR(COUNTIF(#REF!,BB$2),0) -> 0 | BF10: =IFERROR(COUNTIF(#REF!,Analyse!BB$2),0) -> 0 | BG10: =IFERROR(BE10/BF10,0) -> 0 | BH10: =IFERROR(COUNTIF(#REF!,BB$2),0) -> 0 | BI10: =IFERROR(COUNTIF(#REF!,Analyse!BB$2),0) -> 0 | BJ10: =IFERROR(BH10/BI10,0) -> 0 | BK10: JH | BL10: =IFERROR(COUNTIF(#REF!,BL$2),0) -> 0 | BM10: =IFERROR(COUNTIF(#REF!,Analyse!BL$2),0) -> 0 | BN10: =IFERROR(BL10/BM10,0) -> 0 | BO10: =IFERROR(COUNTIF(#REF!,BL$2),0) -> 0 | BP10: =IFERROR(COUNTIF(#REF!,Analyse!BL$2),0) -> 0 | BQ10: =IFERROR(BO10/BP10,0) -> 0 | BR10: =IFERROR(COUNTIF(#REF!,BL$2),0) -> 0 | BS10: =IFERROR(COUNTIF(#REF!,Analyse!BL$2),0) -> 0 | BT10: =IFERROR(BR10/BS10,0) -> 0 | BU10: EB | BV10: =IFERROR(COUNTIF(#REF!,BV$2),0) -> 0 | BW10: =IFERROR(COUNTIF(#REF!,Analyse!BV$2),0) -> 0 | BX10: =IFERROR(BV10/BW10,0) -> 0 | BY10: =IFERROR(COUNTIF(#REF!,BV$2),0) -> 0 | BZ10: =IFERROR(COUNTIF(#REF!,Analyse!BV$2),0) -> 0 | CA10: =IFERROR(BY10/BZ10,0) -> 0 | CB10: =IFERROR(COUNTIF(#REF!,BV$2),0) -> 0 | CC10: =IFERROR(COUNTIF(#REF!,Analyse!BV$2),0) -> 0 | CD10: =IFERROR(CB10/CC10,0) -> 0
C11: ØG | D11: =IFERROR(COUNTIF(#REF!,D$2),0) -> 0 | E11: =IFERROR(COUNTIF(#REF!,Analyse!D$2),0) -> 0 | F11: =IFERROR(D11/E11,0) -> 0 | G11: =IFERROR(COUNTIF(#REF!,D$2),0) -> 0 | H11: =IFERROR(COUNTIF(#REF!,Analyse!D$2),0) -> 0 | I11: =IFERROR(G11/H11,0) -> 0 | J11: =IFERROR(COUNTIF(#REF!,D$2),0) -> 0 | K11: =IFERROR(COUNTIF(#REF!,Analyse!D$2),0) -> 0 | L11: =IFERROR(J11/K11,0) -> 0 | M11: JH | N11: =IFERROR(COUNTIF(#REF!,N$2),0) -> 0 | O11: =IFERROR(COUNTIF(#REF!,Analyse!N$2),0) -> 0 | P11: =IFERROR(N11/O11,0) -> 0 | Q11: =IFERROR(COUNTIF(#REF!,N$2),0) -> 0 | R11: =IFERROR(COUNTIF(#REF!,Analyse!N$2),0) -> 0 | S11: =IFERROR(Q11/R11,0) -> 0 | T11: =IFERROR(COUNTIF(#REF!,N$2),0) -> 0 | U11: =IFERROR(COUNTIF(#REF!,Analyse!N$2),0) -> 0 | V11: =IFERROR(T11/U11,0) -> 0 | W11: ØG | X11: =IFERROR(COUNTIF(#REF!,X$2),0) -> 0 | Y11: =IFERROR(COUNTIF(#REF!,Analyse!X$2),0) -> 0 | Z11: =IFERROR(X11/Y11,0) -> 0 | AA11: =IFERROR(COUNTIF(#REF!,X$2),0) -> 0 | AB11: =IFERROR(COUNTIF(#REF!,Analyse!X$2),0) -> 0 | AC11: =IFERROR(AA11/AB11,0) -> 0 | AD11: =IFERROR(COUNTIF(#REF!,X$2),0) -> 0 | AE11: =IFERROR(COUNTIF(#REF!,Analyse!X$2),0) -> 0 | AF11: =IFERROR(AD11/AE11,0) -> 0 | AG11: AHH | AH11: =IFERROR(COUNTIF(#REF!,AH$2),0) -> 0 | AI11: =IFERROR(COUNTIF(#REF!,Analyse!AH$2),0) -> 0 | AJ11: =IFERROR(AH11/AI11,0) -> 0 | AK11: =IFERROR(COUNTIF(#REF!,AH$2),0) -> 0 | AL11: =IFERROR(COUNTIF(#REF!,Analyse!AH$2),0) -> 0 | AM11: =IFERROR(AK11/AL11,0) -> 0 | AN11: =IFERROR(COUNTIF(#REF!,AH$2),0) -> 0 | AO11: =IFERROR(COUNTIF(#REF!,Analyse!AH$2),0) -> 0 | AP11: =IFERROR(AN11/AO11,0) -> 0 | AQ11: RB | AR11: =IFERROR(COUNTIF(#REF!,AR$2),0) -> 0 | AS11: =IFERROR(COUNTIF(#REF!,Analyse!AR$2),0) -> 0 | AT11: =IFERROR(AR11/AS11,0) -> 0 | AU11: =IFERROR(COUNTIF(#REF!,AR$2),0) -> 0 | AV11: =IFERROR(COUNTIF(#REF!,Analyse!AR$2),0) -> 0 | AW11: =IFERROR(AU11/AV11,0) -> 0 | AX11: =IFERROR(COUNTIF(#REF!,AR$2),0) -> 0 | AY11: =IFERROR(COUNTIF(#REF!,Analyse!AR$2),0) -> 0 | AZ11: =IFERROR(AX11/AY11,0) -> 0 | BA11: RB | BB11: =IFERROR(COUNTIF(#REF!,BB$2),0) -> 0 | BC11: =IFERROR(COUNTIF(#REF!,Analyse!BB$2),0) -> 0 | BD11: =IFERROR(BB11/BC11,0) -> 0 | BE11: =IFERROR(COUNTIF(#REF!,BB$2),0) -> 0 | BF11: =IFERROR(COUNTIF(#REF!,Analyse!BB$2),0) -> 0 | BG11: =IFERROR(BE11/BF11,0) -> 0 | BH11: =IFERROR(COUNTIF(#REF!,BB$2),0) -> 0 | BI11: =IFERROR(COUNTIF(#REF!,Analyse!BB$2),0) -> 0 | BJ11: =IFERROR(BH11/BI11,0) -> 0 | BK11: TOH | BL11: =IFERROR(COUNTIF(#REF!,BL$2),0) -> 0 | BM11: =IFERROR(COUNTIF(#REF!,Analyse!BL$2),0) -> 0 | BN11: =IFERROR(BL11/BM11,0) -> 0 | BO11: =IFERROR(COUNTIF(#REF!,BL$2),0) -> 0 | BP11: =IFERROR(COUNTIF(#REF!,Analyse!BL$2),0) -> 0 | BQ11: =IFERROR(BO11/BP11,0) -> 0 | BR11: =IFERROR(COUNTIF(#REF!,BL$2),0) -> 0 | BS11: =IFERROR(COUNTIF(#REF!,Analyse!BL$2),0) -> 0 | BT11: =IFERROR(BR11/BS11,0) -> 0 | BU11: ØG | BV11: =IFERROR(COUNTIF(#REF!,BV$2),0) -> 0 | BW11: =IFERROR(COUNTIF(#REF!,Analyse!BV$2),0) -> 0 | BX11: =IFERROR(BV11/BW11,0) -> 0 | BY11: =IFERROR(COUNTIF(#REF!,BV$2),0) -> 0 | BZ11: =IFERROR(COUNTIF(#REF!,Analyse!BV$2),0) -> 0 | CA11: =IFERROR(BY11/BZ11,0) -> 0 | CB11: =IFERROR(COUNTIF(#REF!,BV$2),0) -> 0 | CC11: =IFERROR(COUNTIF(#REF!,Analyse!BV$2),0) -> 0 | CD11: =IFERROR(CB11/CC11,0) -> 0
C12: JH | D12: =IFERROR(COUNTIF(#REF!,D$2),0) -> 0 | E12: =IFERROR(COUNTIF(#REF!,Analyse!D$2),0) -> 0 | F12: =IFERROR(D12/E12,0) -> 0 | G12: =IFERROR(COUNTIF(#REF!,D$2),0) -> 0 | H12: =IFERROR(COUNTIF(#REF!,Analyse!D$2),0) -> 0 | I12: =IFERROR(G12/H12,0) -> 0 | J12: =IFERROR(COUNTIF(#REF!,D$2),0) -> 0 | K12: =IFERROR(COUNTIF(#REF!,Analyse!D$2),0) -> 0 | L12: =IFERROR(J12/K12,0) -> 0 | M12: TOH | N12: =IFERROR(COUNTIF(#REF!,N$2),0) -> 0 | O12: =IFERROR(COUNTIF(#REF!,Analyse!N$2),0) -> 0 | P12: =IFERROR(N12/O12,0) -> 0 | Q12: =IFERROR(COUNTIF(#REF!,N$2),0) -> 0 | R12: =IFERROR(COUNTIF(#REF!,Analyse!N$2),0) -> 0 | S12: =IFERROR(Q12/R12,0) -> 0 | T12: =IFERROR(COUNTIF(#REF!,N$2),0) -> 0 | U12: =IFERROR(COUNTIF(#REF!,Analyse!N$2),0) -> 0 | V12: =IFERROR(T12/U12,0) -> 0 | W12: KAF | X12: =IFERROR(COUNTIF(#REF!,X$2),0) -> 0 | Y12: =IFERROR(COUNTIF(#REF!,Analyse!X$2),0) -> 0 | Z12: =IFERROR(X12/Y12,0) -> 0 | AA12: =IFERROR(COUNTIF(#REF!,X$2),0) -> 0 | AB12: =IFERROR(COUNTIF(#REF!,Analyse!X$2),0) -> 0 | AC12: =IFERROR(AA12/AB12,0) -> 0 | AD12: =IFERROR(COUNTIF(#REF!,X$2),0) -> 0 | AE12: =IFERROR(COUNTIF(#REF!,Analyse!X$2),0) -> 0 | AF12: =IFERROR(AD12/AE12,0) -> 0 | AG12: ØG | AH12: =IFERROR(COUNTIF(#REF!,AH$2),0) -> 0 | AI12: =IFERROR(COUNTIF(#REF!,Analyse!AH$2),0) -> 0 | AJ12: =IFERROR(AH12/AI12,0) -> 0 | AK12: =IFERROR(COUNTIF(#REF!,AH$2),0) -> 0 | AL12: =IFERROR(COUNTIF(#REF!,Analyse!AH$2),0) -> 0 | AM12: =IFERROR(AK12/AL12,0) -> 0 | AN12: =IFERROR(COUNTIF(#REF!,AH$2),0) -> 0 | AO12: =IFERROR(COUNTIF(#REF!,Analyse!AH$2),0) -> 0 | AP12: =IFERROR(AN12/AO12,0) -> 0 | AQ12: EB | AR12: =IFERROR(COUNTIF(#REF!,AR$2),0) -> 0 | AS12: =IFERROR(COUNTIF(#REF!,Analyse!AR$2),0) -> 0 | AT12: =IFERROR(AR12/AS12,0) -> 0 | AU12: =IFERROR(COUNTIF(#REF!,AR$2),0) -> 0 | AV12: =IFERROR(COUNTIF(#REF!,Analyse!AR$2),0) -> 0 | AW12: =IFERROR(AU12/AV12,0) -> 0 | AX12: =IFERROR(COUNTIF(#REF!,AR$2),0) -> 0 | AY12: =IFERROR(COUNTIF(#REF!,Analyse!AR$2),0) -> 0 | AZ12: =IFERROR(AX12/AY12,0) -> 0 | BA12: UTG | BB12: =IFERROR(COUNTIF(#REF!,BB$2),0) -> 0 | BC12: =IFERROR(COUNTIF(#REF!,Analyse!BB$2),0) -> 0 | BD12: =IFERROR(BB12/BC12,0) -> 0 | BE12: =IFERROR(COUNTIF(#REF!,BB$2),0) -> 0 | BF12: =IFERROR(COUNTIF(#REF!,Analyse!BB$2),0) -> 0 | BG12: =IFERROR(BE12/BF12,0) -> 0 | BH12: =IFERROR(COUNTIF(#REF!,BB$2),0) -> 0 | BI12: =IFERROR(COUNTIF(#REF!,Analyse!BB$2),0) -> 0 | BJ12: =IFERROR(BH12/BI12,0) -> 0 | BK12: EB | BL12: =IFERROR(COUNTIF(#REF!,BL$2),0) -> 0 | BM12: =IFERROR(COUNTIF(#REF!,Analyse!BL$2),0) -> 0 | BN12: =IFERROR(BL12/BM12,0) -> 0 | BO12: =IFERROR(COUNTIF(#REF!,BL$2),0) -> 0 | BP12: =IFERROR(COUNTIF(#REF!,Analyse!BL$2),0) -> 0 | BQ12: =IFERROR(BO12/BP12,0) -> 0 | BR12: =IFERROR(COUNTIF(#REF!,BL$2),0) -> 0 | BS12: =IFERROR(COUNTIF(#REF!,Analyse!BL$2),0) -> 0 | BT12: =IFERROR(BR12/BS12,0) -> 0 | BU12: UTG | BV12: =IFERROR(COUNTIF(#REF!,BV$2),0) -> 0 | BW12: =IFERROR(COUNTIF(#REF!,Analyse!BV$2),0) -> 0 | BX12: =IFERROR(BV12/BW12,0) -> 0 | BY12: =IFERROR(COUNTIF(#REF!,BV$2),0) -> 0 | BZ12: =IFERROR(COUNTIF(#REF!,Analyse!BV$2),0) -> 0 | CA12: =IFERROR(BY12/BZ12,0) -> 0 | CB12: =IFERROR(COUNTIF(#REF!,BV$2),0) -> 0 | CC12: =IFERROR(COUNTIF(#REF!,Analyse!BV$2),0) -> 0 | CD12: =IFERROR(CB12/CC12,0) -> 0
C13: KAF | D13: =IFERROR(COUNTIF(#REF!,D$2),0) -> 0 | E13: =IFERROR(COUNTIF(#REF!,Analyse!D$2),0) -> 0 | F13: =IFERROR(D13/E13,0) -> 0 | G13: =IFERROR(COUNTIF(#REF!,D$2),0) -> 0 | H13: =IFERROR(COUNTIF(#REF!,Analyse!D$2),0) -> 0 | I13: =IFERROR(G13/H13,0) -> 0 | J13: =IFERROR(COUNTIF(#REF!,D$2),0) -> 0 | K13: =IFERROR(COUNTIF(#REF!,Analyse!D$2),0) -> 0 | L13: =IFERROR(J13/K13,0) -> 0 | M13: EB | N13: =IFERROR(COUNTIF(#REF!,N$2),0) -> 0 | O13: =IFERROR(COUNTIF(#REF!,Analyse!N$2),0) -> 0 | P13: =IFERROR(N13/O13,0) -> 0 | Q13: =IFERROR(COUNTIF(#REF!,N$2),0) -> 0 | R13: =IFERROR(COUNTIF(#REF!,Analyse!N$2),0) -> 0 | S13: =IFERROR(Q13/R13,0) -> 0 | T13: =IFERROR(COUNTIF(#REF!,N$2),0) -> 0 | U13: =IFERROR(COUNTIF(#REF!,Analyse!N$2),0) -> 0 | V13: =IFERROR(T13/U13,0) -> 0 | W13: TOH | X13: =IFERROR(COUNTIF(#REF!,X$2),0) -> 0 | Y13: =IFERROR(COUNTIF(#REF!,Analyse!X$2),0) -> 0 | Z13: =IFERROR(X13/Y13,0) -> 0 | AA13: =IFERROR(COUNTIF(#REF!,X$2),0) -> 0 | AB13: =IFERROR(COUNTIF(#REF!,Analyse!X$2),0) -> 0 | AC13: =IFERROR(AA13/AB13,0) -> 0 | AD13: =IFERROR(COUNTIF(#REF!,X$2),0) -> 0 | AE13: =IFERROR(COUNTIF(#REF!,Analyse!X$2),0) -> 0 | AF13: =IFERROR(AD13/AE13,0) -> 0 | AG13: TOH | AH13: =IFERROR(COUNTIF(#REF!,AH$2),0) -> 0 | AI13: =IFERROR(COUNTIF(#REF!,Analyse!AH$2),0) -> 0 | AJ13: =IFERROR(AH13/AI13,0) -> 0 | AK13: =IFERROR(COUNTIF(#REF!,AH$2),0) -> 0 | AL13: =IFERROR(COUNTIF(#REF!,Analyse!AH$2),0) -> 0 | AM13: =IFERROR(AK13/AL13,0) -> 0 | AN13: =IFERROR(COUNTIF(#REF!,AH$2),0) -> 0 | AO13: =IFERROR(COUNTIF(#REF!,Analyse!AH$2),0) -> 0 | AP13: =IFERROR(AN13/AO13,0) -> 0 | AQ13: JH | AR13: =IFERROR(COUNTIF(#REF!,AR$2),0) -> 0 | AS13: =IFERROR(COUNTIF(#REF!,Analyse!AR$2),0) -> 0 | AT13: =IFERROR(AR13/AS13,0) -> 0 | AU13: =IFERROR(COUNTIF(#REF!,AR$2),0) -> 0 | AV13: =IFERROR(COUNTIF(#REF!,Analyse!AR$2),0) -> 0 | AW13: =IFERROR(AU13/AV13,0) -> 0 | AX13: =IFERROR(COUNTIF(#REF!,AR$2),0) -> 0 | AY13: =IFERROR(COUNTIF(#REF!,Analyse!AR$2),0) -> 0 | AZ13: =IFERROR(AX13/AY13,0) -> 0 | BA13: KAF | BB13: =IFERROR(COUNTIF(#REF!,BB$2),0) -> 0 | BC13: =IFERROR(COUNTIF(#REF!,Analyse!BB$2),0) -> 0 | BD13: =IFERROR(BB13/BC13,0) -> 0 | BE13: =IFERROR(COUNTIF(#REF!,BB$2),0) -> 0 | BF13: =IFERROR(COUNTIF(#REF!,Analyse!BB$2),0) -> 0 | BG13: =IFERROR(BE13/BF13,0) -> 0 | BH13: =IFERROR(COUNTIF(#REF!,BB$2),0) -> 0 | BI13: =IFERROR(COUNTIF(#REF!,Analyse!BB$2),0) -> 0 | BJ13: =IFERROR(BH13/BI13,0) -> 0 | BK13: AHH | BL13: =IFERROR(COUNTIF(#REF!,BL$2),0) -> 0 | BM13: =IFERROR(COUNTIF(#REF!,Analyse!BL$2),0) -> 0 | BN13: =IFERROR(BL13/BM13,0) -> 0 | BO13: =IFERROR(COUNTIF(#REF!,BL$2),0) -> 0 | BP13: =IFERROR(COUNTIF(#REF!,Analyse!BL$2),0) -> 0 | BQ13: =IFERROR(BO13/BP13,0) -> 0 | BR13: =IFERROR(COUNTIF(#REF!,BL$2),0) -> 0 | BS13: =IFERROR(COUNTIF(#REF!,Analyse!BL$2),0) -> 0 | BT13: =IFERROR(BR13/BS13,0) -> 0 | BU13: LEV | BV13: =IFERROR(COUNTIF(#REF!,BV$2),0) -> 0 | BW13: =IFERROR(COUNTIF(#REF!,Analyse!BV$2),0) -> 0 | BX13: =IFERROR(BV13/BW13,0) -> 0 | BY13: =IFERROR(COUNTIF(#REF!,BV$2),0) -> 0 | BZ13: =IFERROR(COUNTIF(#REF!,Analyse!BV$2),0) -> 0 | CA13: =IFERROR(BY13/BZ13,0) -> 0 | CB13: =IFERROR(COUNTIF(#REF!,BV$2),0) -> 0 | CC13: =IFERROR(COUNTIF(#REF!,Analyse!BV$2),0) -> 0 | CD13: =IFERROR(CB13/CC13,0) -> 0
B15: =COUNTIF(#REF!,80) -> #REF!
D17: %-treff
D18: =$D$2 -> 80 | I18: =$N$2 -> 70 | N18: 60 | S18: 50 | X18: 40 | AC18: 30 | AH18: 20 | AM18: 10
D19: H | E19: U | F19: B | I19: H | J19: U | K19: B | N19: H | O19: U | P19: B | S19: H | T19: U | U19: B | X19: H | Y19: U | Z19: B | AC19: H | AD19: U | AE19: B | AH19: H | AI19: U | AJ19: B | AM19: H | AN19: U | AO19: B
C20: AHH | D20: =F5 -> 0 | E20: =I5 -> 0 | F20: =L5 -> 0 | H20: AHH | I20: =P5 -> 0 | J20: =S5 -> 0 | K20: =V5 -> 0 | M20: AHH | N20: =Z5 -> 0 | O20: =AC5 -> 0 | P20: =AF5 -> 0 | R20: AHH | S20: =AJ5 -> 0 | T20: =AM5 -> 0 | U20: =AP5 -> 0 | W20: AHH | X20: =AT5 -> 0 | Y20: =AW5 -> 0 | Z20: =AZ5 -> 0 | AB20: AHH | AC20: =BD5 -> 0 | AD20: =BG5 -> 0 | AE20: =BG5 -> 0 | AG20: AHH | AH20: =BN5 -> 0 | AI20: =BQ5 -> 0 | AJ20: =BT5 -> 0 | AL20: AHH | AM20: =BX5 -> 0 | AN20: =CA5 -> 0 | AO20: =CD5 -> 0
C21: RB | D21: =F6 -> 0 | E21: =I6 -> 0 | F21: =L6 -> 0 | H21: RB | I21: =P6 -> 0 | J21: =S6 -> 0 | K21: =V6 -> 0 | M21: RB | N21: =Z6 -> 0 | O21: =AC6 -> 0 | P21: =AF6 -> 0 | R21: RB | S21: =AJ6 -> 0 | T21: =AM6 -> 0 | U21: =AP6 -> 0 | W21: RB | X21: =AT6 -> 0 | Y21: =AW6 -> 0 | Z21: =AZ6 -> 0 | AB21: RB | AC21: =BD6 -> 0 | AD21: =BG6 -> 0 | AE21: =BG6 -> 0 | AG21: RB | AH21: =BN6 -> 0 | AI21: =BQ6 -> 0 | AJ21: =BT6 -> 0 | AL21: RB | AM21: =BX6 -> 0 | AN21: =CA6 -> 0 | AO21: =CD6 -> 0
C22: EB | D22: =F7 -> 0 | E22: =I7 -> 0 | F22: =L7 -> 0 | H22: EB | I22: =P7 -> 0 | J22: =S7 -> 0 | K22: =V7 -> 0 | M22: EB | N22: =Z7 -> 0 | O22: =AC7 -> 0 | P22: =AF7 -> 0 | R22: EB | S22: =AJ7 -> 0 | T22: =AM7 -> 0 | U22: =AP7 -> 0 | W22: EB | X22: =AT7 -> 0 | Y22: =AW7 -> 0 | Z22: =AZ7 -> 0 | AB22: EB | AC22: =BD7 -> 0 | AD22: =BG7 -> 0 | AE22: =BG7 -> 0 | AG22: EB | AH22: =BN7 -> 0 | AI22: =BQ7 -> 0 | AJ22: =BT7 -> 0 | AL22: EB | AM22: =BX7 -> 0 | AN22: =CA7 -> 0 | AO22: =CD7 -> 0
C23: KAF | D23: =F8 -> 0 | E23: =I8 -> 0 | F23: =L8 -> 0 | H23: KAF | I23: =P8 -> 0 | J23: =S8 -> 0 | K23: =V8 -> 0 | M23: KAF | N23: =Z8 -> 0 | O23: =AC8 -> 0 | P23: =AF8 -> 0 | R23: KAF | S23: =AJ8 -> 0 | T23: =AM8 -> 0 | U23: =AP8 -> 0 | W23: KAF | X23: =AT8 -> 0 | Y23: =AW8 -> 0 | Z23: =AZ8 -> 0 | AB23: KAF | AC23: =BD8 -> 0 | AD23: =BG8 -> 0 | AE23: =BG8 -> 0 | AG23: KAF | AH23: =BN8 -> 0 | AI23: =BQ8 -> 0 | AJ23: =BT8 -> 0 | AL23: KAF | AM23: =BX8 -> 0 | AN23: =CA8 -> 0 | AO23: =CD8 -> 0
C24: ØG | D24: =F9 -> 0 | E24: =I9 -> 0 | F24: =L9 -> 0 | H24: ØG | I24: =P9 -> 0 | J24: =S9 -> 0 | K24: =V9 -> 0 | M24: ØG | N24: =Z9 -> 0 | O24: =AC9 -> 0 | P24: =AF9 -> 0 | R24: ØG | S24: =AJ9 -> 0 | T24: =AM9 -> 0 | U24: =AP9 -> 0 | W24: ØG | X24: =AT9 -> 0 | Y24: =AW9 -> 0 | Z24: =AZ9 -> 0 | AB24: ØG | AC24: =BD9 -> 0 | AD24: =BG9 -> 0 | AE24: =BG9 -> 0 | AG24: ØG | AH24: =BN9 -> 0 | AI24: =BQ9 -> 0 | AJ24: =BT9 -> 0 | AL24: ØG | AM24: =BX9 -> 0 | AN24: =CA9 -> 0 | AO24: =CD9 -> 0
C25: JH | D25: =F10 -> 0 | E25: =I10 -> 0 | F25: =L10 -> 0 | H25: JH | I25: =P10 -> 0 | J25: =S10 -> 0 | K25: =V10 -> 0 | M25: JH | N25: =Z10 -> 0 | O25: =AC10 -> 0 | P25: =AF10 -> 0 | R25: JH | S25: =AJ10 -> 0 | T25: =AM10 -> 0 | U25: =AP10 -> 0 | W25: JH | X25: =AT10 -> 0 | Y25: =AW10 -> 0 | Z25: =AZ10 -> 0 | AB25: JH | AC25: =BD10 -> 0 | AD25: =BG10 -> 0 | AE25: =BG10 -> 0 | AG25: JH | AH25: =BN10 -> 0 | AI25: =BQ10 -> 0 | AJ25: =BT10 -> 0 | AL25: JH | AM25: =BX10 -> 0 | AN25: =CA10 -> 0 | AO25: =CD10 -> 0
C26: TOH | D26: =F11 -> 0 | E26: =I11 -> 0 | F26: =L11 -> 0 | H26: TOH | I26: =P11 -> 0 | J26: =S11 -> 0 | K26: =V11 -> 0 | M26: TOH | N26: =Z11 -> 0 | O26: =AC11 -> 0 | P26: =AF11 -> 0 | R26: TOH | S26: =AJ11 -> 0 | T26: =AM11 -> 0 | U26: =AP11 -> 0 | W26: TOH | X26: =AT11 -> 0 | Y26: =AW11 -> 0 | Z26: =AZ11 -> 0 | AB26: TOH | AC26: =BD11 -> 0 | AD26: =BG11 -> 0 | AE26: =BG11 -> 0 | AG26: TOH | AH26: =BN11 -> 0 | AI26: =BQ11 -> 0 | AJ26: =BT11 -> 0 | AL26: TOH | AM26: =BX11 -> 0 | AN26: =CA11 -> 0 | AO26: =CD11 -> 0
C27: UTG | D27: =F12 -> 0 | E27: =I12 -> 0 | F27: =L12 -> 0 | H27: UTG | I27: =P12 -> 0 | J27: =S12 -> 0 | K27: =V12 -> 0 | M27: UTG | N27: =Z12 -> 0 | O27: =AC12 -> 0 | P27: =AF12 -> 0 | R27: UTG | S27: =AJ12 -> 0 | T27: =AM12 -> 0 | U27: =AP12 -> 0 | W27: UTG | X27: =AT12 -> 0 | Y27: =AW12 -> 0 | Z27: =AZ12 -> 0 | AB27: UTG | AC27: =BD12 -> 0 | AD27: =BG12 -> 0 | AE27: =BG12 -> 0 | AG27: UTG | AH27: =BN12 -> 0 | AI27: =BQ12 -> 0 | AJ27: =BT12 -> 0 | AL27: UTG | AM27: =BX12 -> 0 | AN27: =CA12 -> 0 | AO27: =CD12 -> 0
C28: LEV | D28: =F13 -> 0 | E28: =I13 -> 0 | F28: =L13 -> 0 | H28: LEV | I28: =P13 -> 0 | J28: =S13 -> 0 | K28: =V13 -> 0 | M28: LEV | N28: =Z13 -> 0 | O28: =AC13 -> 0 | P28: =AF13 -> 0 | R28: LEV | S28: =AJ13 -> 0 | T28: =AM13 -> 0 | U28: =AP13 -> 0 | W28: LEV | X28: =AT13 -> 0 | Y28: =AW13 -> 0 | Z28: =AZ13 -> 0 | AB28: LEV | AC28: =BD13 -> 0 | AD28: =BG13 -> 0 | AE28: =BG13 -> 0 | AG28: LEV | AH28: =BN13 -> 0 | AI28: =BQ13 -> 0 | AJ28: =BT13 -> 0 | AL28: LEV | AM28: =BX13 -> 0 | AN28: =CA13 -> 0 | AO28: =CD13 -> 0
G31: 1 | H31: 1 | I31: 1
D32: Gjennomsnitt | G32: Oppnådd:
D33: H | E33: U | F33: B | G33: H | H33: U | I33: B | J33: Rang1 | K33: Rang 2 | N33: H | O33: U | P33: B | R33: Analyse
C34: AHH | D34: =AVERAGE(D20,I20,N20,S20,X20,AC20,AH20,AM20) -> 0 | E34: =AVERAGE(E20,J20,O20,T20,Y20,AD20,AI20,AN20) -> 0 | F34: =AVERAGE(F20,K20,P20,U20,Z20,AE20,AJ20,AO20) -> 0 | G34: =SUM(D20,I20,N20,S20,X20,AC20,AH20,AM20) -> 0 | H34: =SUM(E20,J20,O20,T20,Y20,AD20,AI20,AN20) -> 0 | I34: =SUM(F20,K20,P20,U20,Z20,AE20,AJ20,AO20) -> 0 | J34: =_xlfn.RANK.EQ(G34,$G$34:$G$42)*$G$31+_xlfn.RANK.EQ(H34,$H$34:$H$42,-1)*$H$31+_xlfn.RANK.EQ(I34,$I$34:$I$42,-1)*$I$31 -> 3 | K34: =_xlfn.RANK.EQ(J34,$J$34:$J$42)+COUNTIF($J$34:J34,J34)-1 -> 1 | L34: 1 | M34: =_xlfn.XLOOKUP(L34,$K$34:$K$42,$C$34:$C$42) -> AHH | N34: =_xlfn.XLOOKUP($M34,$C$34:$C$42,G$34:G$42) -> 0 | O34: =_xlfn.SINGLE(_xlfn.XLOOKUP($M34,$C$34:$C$42,H$34:H$42)) -> 0 | P34: =_xlfn.SINGLE(_xlfn.XLOOKUP($M34,$C$34:$C$42,I$34:I$42)) -> 0 | R34: =_xlfn.XLOOKUP(LARGE($N$34:$N$42,1),$N$34:$N$42,$M$34:$M$42)&" er vår beste tipper på hjemmekamper" -> AHH er vår beste tipper på hjemmekamper
C35: RB | D35: =AVERAGE(D21,I21,N21,S21,X21,AC21,AH21,AM21) -> 0 | E35: =AVERAGE(E21,J21,O21,T21,Y21,AD21,AI21,AN21) -> 0 | F35: =AVERAGE(F21,K21,P21,U21,Z21,AE21,AJ21,AO21) -> 0 | G35: =SUM(D21,I21,N21,S21,X21,AC21,AH21,AM21) -> 0 | H35: =SUM(E21,J21,O21,T21,Y21,AD21,AI21,AN21) -> 0 | I35: =SUM(F21,K21,P21,U21,Z21,AE21,AJ21,AO21) -> 0 | J35: =_xlfn.RANK.EQ(G35,$G$34:$G$42,-1)*$G$31+_xlfn.RANK.EQ(H35,$H$34:$H$42,-1)*$H$31+_xlfn.RANK.EQ(I35,$I$34:$I$42,-1)*$I$31 -> 3 | K35: =_xlfn.RANK.EQ(J35,$J$34:$J$42)+COUNTIF($J$34:J35,J35)-1 -> 2 | L35: 2 | M35: =_xlfn.XLOOKUP(L35,$K$34:$K$42,$C$34:$C$42) -> RB | N35: =_xlfn.SINGLE(_xlfn.XLOOKUP($M35,$C$34:$C$42,G$34:G$42)) -> 0 | O35: =_xlfn.SINGLE(_xlfn.XLOOKUP($M35,$C$34:$C$42,H$34:H$42)) -> 0 | P35: =_xlfn.SINGLE(_xlfn.XLOOKUP($M35,$C$34:$C$42,I$34:I$42)) -> 0 | R35: =_xlfn.XLOOKUP(LARGE($O$34:$O$42,1),$O$34:$O$42,$M$34:$M$42)&" er vår beste tipper på uavgjorte kamper" -> AHH er vår beste tipper på uavgjorte kamper
C36: EB | D36: =AVERAGE(D22,I22,N22,S22,X22,AC22,AH22,AM22) -> 0 | E36: =AVERAGE(E22,J22,O22,T22,Y22,AD22,AI22,AN22) -> 0 | F36: =AVERAGE(F22,K22,P22,U22,Z22,AE22,AJ22,AO22) -> 0 | G36: =SUM(D22,I22,N22,S22,X22,AC22,AH22,AM22) -> 0 | H36: =SUM(E22,J22,O22,T22,Y22,AD22,AI22,AN22) -> 0 | I36: =SUM(F22,K22,P22,U22,Z22,AE22,AJ22,AO22) -> 0 | J36: =_xlfn.RANK.EQ(G36,$G$34:$G$42,-1)*$G$31+_xlfn.RANK.EQ(H36,$H$34:$H$42,-1)*$H$31+_xlfn.RANK.EQ(I36,$I$34:$I$42,-1)*$I$31 -> 3 | K36: =_xlfn.RANK.EQ(J36,$J$34:$J$42)+COUNTIF($J$34:J36,J36)-1 -> 3 | L36: 3 | M36: =_xlfn.XLOOKUP(L36,$K$34:$K$42,$C$34:$C$42) -> EB | N36: =_xlfn.SINGLE(_xlfn.XLOOKUP($M36,$C$34:$C$42,G$34:G$42)) -> 0 | O36: =_xlfn.SINGLE(_xlfn.XLOOKUP($M36,$C$34:$C$42,H$34:H$42)) -> 0 | P36: =_xlfn.SINGLE(_xlfn.XLOOKUP($M36,$C$34:$C$42,I$34:I$42)) -> 0 | R36: =_xlfn.XLOOKUP(LARGE($P$34:$P$42,1),$P$34:$P$42,$M$34:$M$42)&" er vår beste tipper på bortekamper" -> AHH er vår beste tipper på bortekamper
C37: KAF | D37: =AVERAGE(D23,I23,N23,S23,X23,AC23,AH23,AM23) -> 0 | E37: =AVERAGE(E23,J23,O23,T23,Y23,AD23,AI23,AN23) -> 0 | F37: =AVERAGE(F23,K23,P23,U23,Z23,AE23,AJ23,AO23) -> 0 | G37: =SUM(D23,I23,N23,S23,X23,AC23,AH23,AM23) -> 0 | H37: =SUM(E23,J23,O23,T23,Y23,AD23,AI23,AN23) -> 0 | I37: =SUM(F23,K23,P23,U23,Z23,AE23,AJ23,AO23) -> 0 | J37: =_xlfn.RANK.EQ(G37,$G$34:$G$42,-1)*$G$31+_xlfn.RANK.EQ(H37,$H$34:$H$42,-1)*$H$31+_xlfn.RANK.EQ(I37,$I$34:$I$42,-1)*$I$31 -> 3 | K37: =_xlfn.RANK.EQ(J37,$J$34:$J$42)+COUNTIF($J$34:J37,J37)-1 -> 4 | L37: 4 | M37: =_xlfn.XLOOKUP(L37,$K$34:$K$42,$C$34:$C$42) -> KAF | N37: =_xlfn.SINGLE(_xlfn.XLOOKUP($M37,$C$34:$C$42,G$34:G$42)) -> 0 | O37: =_xlfn.SINGLE(_xlfn.XLOOKUP($M37,$C$34:$C$42,H$34:H$42)) -> 0 | P37: =_xlfn.SINGLE(_xlfn.XLOOKUP($M37,$C$34:$C$42,I$34:I$42)) -> 0
C38: ØG | D38: =AVERAGE(D24,I24,N24,S24,X24,AC24,AH24,AM24) -> 0 | E38: =AVERAGE(E24,J24,O24,T24,Y24,AD24,AI24,AN24) -> 0 | F38: =AVERAGE(F24,K24,P24,U24,Z24,AE24,AJ24,AO24) -> 0 | G38: =SUM(D24,I24,N24,S24,X24,AC24,AH24,AM24) -> 0 | H38: =SUM(E24,J24,O24,T24,Y24,AD24,AI24,AN24) -> 0 | I38: =SUM(F24,K24,P24,U24,Z24,AE24,AJ24,AO24) -> 0 | J38: =_xlfn.RANK.EQ(G38,$G$34:$G$42,-1)*$G$31+_xlfn.RANK.EQ(H38,$H$34:$H$42,-1)*$H$31+_xlfn.RANK.EQ(I38,$I$34:$I$42,-1)*$I$31 -> 3 | K38: =_xlfn.RANK.EQ(J38,$J$34:$J$42)+COUNTIF($J$34:J38,J38)-1 -> 5 | L38: 5 | M38: =_xlfn.XLOOKUP(L38,$K$34:$K$42,$C$34:$C$42) -> ØG | N38: =_xlfn.SINGLE(_xlfn.XLOOKUP($M38,$C$34:$C$42,G$34:G$42)) -> 0 | O38: =_xlfn.SINGLE(_xlfn.XLOOKUP($M38,$C$34:$C$42,H$34:H$42)) -> 0 | P38: =_xlfn.SINGLE(_xlfn.XLOOKUP($M38,$C$34:$C$42,I$34:I$42)) -> 0 | R38: =C5&" er tippelagets beste på 80-tips. Han har truffet på "&D5&" av "&E5&" hjemmetips" -> RB er tippelagets beste på 80-tips. Han har truffet på 0 av 0 hjemmetips
C39: JH | D39: =AVERAGE(D25,I25,N25,S25,X25,AC25,AH25,AM25) -> 0 | E39: =AVERAGE(E25,J25,O25,T25,Y25,AD25,AI25,AN25) -> 0 | F39: =AVERAGE(F25,K25,P25,U25,Z25,AE25,AJ25,AO25) -> 0 | G39: =SUM(D25,I25,N25,S25,X25,AC25,AH25,AM25) -> 0 | H39: =SUM(E25,J25,O25,T25,Y25,AD25,AI25,AN25) -> 0 | I39: =SUM(F25,K25,P25,U25,Z25,AE25,AJ25,AO25) -> 0 | J39: =_xlfn.RANK.EQ(G39,$G$34:$G$42,-1)*$G$31+_xlfn.RANK.EQ(H39,$H$34:$H$42,-1)*$H$31+_xlfn.RANK.EQ(I39,$I$34:$I$42,-1)*$I$31 -> 3 | K39: =_xlfn.RANK.EQ(J39,$J$34:$J$42)+COUNTIF($J$34:J39,J39)-1 -> 6 | L39: 6 | M39: =_xlfn.XLOOKUP(L39,$K$34:$K$42,$C$34:$C$42) -> JH | N39: =_xlfn.SINGLE(_xlfn.XLOOKUP($M39,$C$34:$C$42,G$34:G$42)) -> 0 | O39: =_xlfn.SINGLE(_xlfn.XLOOKUP($M39,$C$34:$C$42,H$34:H$42)) -> 0 | P39: =_xlfn.SINGLE(_xlfn.XLOOKUP($M39,$C$34:$C$42,I$34:I$42)) -> 0
C40: TOH | D40: =AVERAGE(D26,I26,N26,S26,X26,AC26,AH26,AM26) -> 0 | E40: =AVERAGE(E26,J26,O26,T26,Y26,AD26,AI26,AN26) -> 0 | F40: =AVERAGE(F26,K26,P26,U26,Z26,AE26,AJ26,AO26) -> 0 | G40: =SUM(D26,I26,N26,S26,X26,AC26,AH26,AM26) -> 0 | H40: =SUM(E26,J26,O26,T26,Y26,AD26,AI26,AN26) -> 0 | I40: =SUM(F26,K26,P26,U26,Z26,AE26,AJ26,AO26) -> 0 | J40: =_xlfn.RANK.EQ(G40,$G$34:$G$42,-1)*$G$31+_xlfn.RANK.EQ(H40,$H$34:$H$42,-1)*$H$31+_xlfn.RANK.EQ(I40,$I$34:$I$42,-1)*$I$31 -> 3 | K40: =_xlfn.RANK.EQ(J40,$J$34:$J$42)+COUNTIF($J$34:J40,J40)-1 -> 7 | L40: 7 | M40: =_xlfn.XLOOKUP(L40,$K$34:$K$42,$C$34:$C$42) -> TOH | N40: =_xlfn.SINGLE(_xlfn.XLOOKUP($M40,$C$34:$C$42,G$34:G$42)) -> 0 | O40: =_xlfn.SINGLE(_xlfn.XLOOKUP($M40,$C$34:$C$42,H$34:H$42)) -> 0 | P40: =_xlfn.SINGLE(_xlfn.XLOOKUP($M40,$C$34:$C$42,I$34:I$42)) -> 0
C41: UTG | D41: =AVERAGE(D27,I27,N27,S27,X27,AC27,AH27,AM27) -> 0 | E41: =AVERAGE(E27,J27,O27,T27,Y27,AD27,AI27,AN27) -> 0 | F41: =AVERAGE(F27,K27,P27,U27,Z27,AE27,AJ27,AO27) -> 0 | G41: =SUM(D27,I27,N27,S27,X27,AC27,AH27,AM27) -> 0 | H41: =SUM(E27,J27,O27,T27,Y27,AD27,AI27,AN27) -> 0 | I41: =SUM(F27,K27,P27,U27,Z27,AE27,AJ27,AO27) -> 0 | J41: =_xlfn.RANK.EQ(G41,$G$34:$G$42,-1)*$G$31+_xlfn.RANK.EQ(H41,$H$34:$H$42,-1)*$H$31+_xlfn.RANK.EQ(I41,$I$34:$I$42,-1)*$I$31 -> 3 | K41: =_xlfn.RANK.EQ(J41,$J$34:$J$42)+COUNTIF($J$34:J41,J41)-1 -> 8 | L41: 8 | M41: =_xlfn.XLOOKUP(L41,$K$34:$K$42,$C$34:$C$42) -> UTG | N41: =_xlfn.SINGLE(_xlfn.XLOOKUP($M41,$C$34:$C$42,G$34:G$42)) -> 0 | O41: =_xlfn.SINGLE(_xlfn.XLOOKUP($M41,$C$34:$C$42,H$34:H$42)) -> 0 | P41: =_xlfn.SINGLE(_xlfn.XLOOKUP($M41,$C$34:$C$42,I$34:I$42)) -> 0
C42: LEV | D42: =AVERAGE(D28,I28,N28,S28,X28,AC28,AH28,AM28) -> 0 | E42: =AVERAGE(E28,J28,O28,T28,Y28,AD28,AI28,AN28) -> 0 | F42: =AVERAGE(F28,K28,P28,U28,Z28,AE28,AJ28,AO28) -> 0 | G42: =SUM(D28,I28,N28,S28,X28,AC28,AH28,AM28) -> 0 | H42: =SUM(E28,J28,O28,T28,Y28,AD28,AI28,AN28) -> 0 | I42: =SUM(F28,K28,P28,U28,Z28,AE28,AJ28,AO28) -> 0 | J42: =_xlfn.RANK.EQ(G42,$G$34:$G$42,-1)*$G$31+_xlfn.RANK.EQ(H42,$H$34:$H$42,-1)*$H$31+_xlfn.RANK.EQ(I42,$I$34:$I$42,-1)*$I$31 -> 3 | K42: =_xlfn.RANK.EQ(J42,$J$34:$J$42)+COUNTIF($J$34:J42,J42)-1 -> 9 | L42: 9 | M42: =_xlfn.XLOOKUP(L42,$K$34:$K$42,$C$34:$C$42) -> LEV | N42: =_xlfn.SINGLE(_xlfn.XLOOKUP($M42,$C$34:$C$42,G$34:G$42)) -> 0 | O42: =_xlfn.SINGLE(_xlfn.XLOOKUP($M42,$C$34:$C$42,H$34:H$42)) -> 0 | P42: =_xlfn.SINGLE(_xlfn.XLOOKUP($M42,$C$34:$C$42,I$34:I$42)) -> 0
D47: Leverte | G47: Treff
D48: H | E48: U | F48: B | G48: H | H48: U | I48: B
C49: AHH | D49: =SUM(E5+O5+Y5+AI5+AS5+BC5+BM5+BW5) -> 0 | E49: =SUM(H5+R5+AB5+AL5+AV5+BF5+BP5+BZ5) -> 0 | F49: =SUM(K5+U5+AE5+AO5+AY5+BI5+BS5+CC5) -> 0 | G49: =SUM(D5+N5+X5+AH5+AR5+BB5+BL5+BV5) -> 0 | H49: =SUM(G5+Q5+AA5+AK5+AU5+BE5+BO5+BY5) -> 0 | I49: =SUM(J5+T5+AD5+AN5+AX5+BH5+BR5+CB5) -> 0
...

Sheet Statistikk
B1: Dato | C1: ahh | D1: rb | E1: eb | F1: kaf | G1: øg | H1: jh | I1: toh | J1: utg | K1: lev | O1: AHH | P1: Dato | Q1: ahh | R1: rb | S1: eb | T1: kaf | U1: øg | V1: jh | W1: toh | X1: utg | Y1: lev | AB1: Ukens Vinner | AM1: Ukens Jumbo
A2: 1 | B2: =#REF! -> #REF! | C2: =_xlfn.XLOOKUP(t_rang[[#This Row],[Dato]],#REF!,#REF!) -> #REF! | D2: =_xlfn.XLOOKUP(t_rang[[#This Row],[Dato]],#REF!,#REF!) -> #REF! | E2: =_xlfn.XLOOKUP(t_rang[[#This Row],[Dato]],#REF!,#REF!) -> #REF! | F2: =_xlfn.XLOOKUP(t_rang[[#This Row],[Dato]],#REF!,#REF!) -> #REF! | G2: =_xlfn.XLOOKUP(t_rang[[#This Row],[Dato]],#REF!,#REF!) -> #REF! | H2: =_xlfn.XLOOKUP(t_rang[[#This Row],[Dato]],#REF!,#REF!) -> #REF! | I2: =_xlfn.XLOOKUP(t_rang[[#This Row],[Dato]],#REF!,#REF!) -> #REF! | J2: =_xlfn.XLOOKUP(t_rang[[#This Row],[Dato]],#REF!,#REF!) -> #REF! | K2: =_xlfn.XLOOKUP(t_rang[[#This Row],[Dato]],#REF!,#REF!) -> #REF! | P2: =#REF! -> #REF! | Q2: =#REF! -> #REF! | R2: =#REF! -> #REF! | S2: =#REF! -> #REF! | T2: =#REF! -> #REF! | U2: =#REF! -> #REF! | V2: =#REF! -> #REF! | W2: =#REF! -> #REF! | ... Y2: =#REF! -> #REF! | AA2: =t_tp[[#This Row],[Dato]] -> #REF! | AB2: {=IFERROR(_xlfn._xlws.FILTER($Q$1:$Y$1,t_tp[[#This Row],[ahh]:[lev]]=LARGE(t_tp[[#This Row],[ahh]:[lev]],1)),"")} | AL2: =AA2 -> #REF! | AM2: {=IFERROR(_xlfn._xlws.FILTER($Q$1:$Y$1,t_tp[[#This Row],[ahh]:[lev]]=SMALL(t_tp[[#This Row],[ahh]:[lev]],1)),"")}
A3: 2 | B3: =#REF! -> #REF! | C3: =_xlfn.XLOOKUP(t_rang[[#This Row],[Dato]],#REF!,#REF!) -> #REF! | D3: =_xlfn.XLOOKUP(t_rang[[#This Row],[Dato]],#REF!,#REF!) -> #REF! | E3: =_xlfn.XLOOKUP(t_rang[[#This Row],[Dato]],#REF!,#REF!) -> #REF! | F3: =_xlfn.XLOOKUP(t_rang[[#This Row],[Dato]],#REF!,#REF!) -> #REF! | G3: =_xlfn.XLOOKUP(t_rang[[#This Row],[Dato]],#REF!,#REF!) -> #REF! | H3: =_xlfn.XLOOKUP(t_rang[[#This Row],[Dato]],#REF!,#REF!) -> #REF! | I3: =_xlfn.XLOOKUP(t_rang[[#This Row],[Dato]],#REF!,#REF!) -> #REF! | J3: =_xlfn.XLOOKUP(t_rang[[#This Row],[Dato]],#REF!,#REF!) -> #REF! | K3: =_xlfn.XLOOKUP(t_rang[[#This Row],[Dato]],#REF!,#REF!) -> #REF! | P3: =#REF! -> #REF! | Q3: =#REF! -> #REF! | R3: =#REF! -> #REF! | S3: =#REF! -> #REF! | T3: =#REF! -> #REF! | U3: =#REF! -> #REF! | V3: =#REF! -> #REF! | W3: =#REF! -> #REF! | ... Y3: =#REF! -> #REF! | AA3: =t_tp[[#This Row],[Dato]] -> #REF! | AB3: {=IFERROR(_xlfn._xlws.FILTER($Q$1:$Y$1,t_tp[[#This Row],[ahh]:[lev]]=LARGE(t_tp[[#This Row],[ahh]:[lev]],1)),"")} | AL3: =AA3 -> #REF! | AM3: {=IFERROR(_xlfn._xlws.FILTER($Q$1:$Y$1,t_tp[[#This Row],[ahh]:[lev]]=SMALL(t_tp[[#This Row],[ahh]:[lev]],1)),"")}
A4: 3 | B4: =#REF! -> #REF! | C4: =_xlfn.XLOOKUP(t_rang[[#This Row],[Dato]],#REF!,#REF!) -> #REF! | D4: =_xlfn.XLOOKUP(t_rang[[#This Row],[Dato]],#REF!,#REF!) -> #REF! | E4: =_xlfn.XLOOKUP(t_rang[[#This Row],[Dato]],#REF!,#REF!) -> #REF! | F4: =_xlfn.XLOOKUP(t_rang[[#This Row],[Dato]],#REF!,#REF!) -> #REF! | G4: =_xlfn.XLOOKUP(t_rang[[#This Row],[Dato]],#REF!,#REF!) -> #REF! | H4: =_xlfn.XLOOKUP(t_rang[[#This Row],[Dato]],#REF!,#REF!) -> #REF! | I4: =_xlfn.XLOOKUP(t_rang[[#This Row],[Dato]],#REF!,#REF!) -> #REF! | J4: =_xlfn.XLOOKUP(t_rang[[#This Row],[Dato]],#REF!,#REF!) -> #REF! | K4: =_xlfn.XLOOKUP(t_rang[[#This Row],[Dato]],#REF!,#REF!) -> #REF! | P4: =#REF! -> #REF! | Q4: =#REF! -> #REF! | R4: =#REF! -> #REF! | S4: =#REF! -> #REF! | T4: =#REF! -> #REF! | U4: =#REF! -> #REF! | V4: =#REF! -> #REF! | W4: =#REF! -> #REF! | ... Y4: =#REF! -> #REF! | AA4: =t_tp[[#This Row],[Dato]] -> #REF! | AB4: {=IFERROR(_xlfn._xlws.FILTER($Q$1:$Y$1,t_tp[[#This Row],[ahh]:[lev]]=LARGE(t_tp[[#This Row],[ahh]:[lev]],1)),"")} | AL4: =AA4 -> #REF! | AM4: {=IFERROR(_xlfn._xlws.FILTER($Q$1:$Y$1,t_tp[[#This Row],[ahh]:[lev]]=SMALL(t_tp[[#This Row],[ahh]:[lev]],1)),"")}
